Workbook

Sheet Leg 1
A1: Table of 32 | B1: Table of 16 | C1: Table of 8 | D1: Semi-Finals | E1: Finals | I1: right.fencer | J1: left.fencer | K1: winner | L1: score
H2: 1 | I2: =INDIRECT("A" & (3 + ($H2-1)*4)) -> (1) LARRAZABAL ALEXA NTP / PHI | J2: =INDIRECT("A" & (5 + ($H2-1)*4)) -> (32) TRINIDAD SOLANA MAYUMI EZKRIMA / PHI | K2: =INDIRECT("B" & (4 + ($H2-1)*4)) -> (1) LARRAZABAL ALEXA | L2: =INDIRECT("B" & (5 + ($H2-1)*4)) -> 15 - 5
A3: (1) LARRAZABAL ALEXA NTP / PHI | H3: 2 | I3: =INDIRECT("A" & (3 + ($H3-1)*4)) -> (17) MANAOIS IRISH UE / PHI | J3: =INDIRECT("A" & (5 + ($H3-1)*4)) -> (16) ONG JICKLE CLAIN CF / PHI | K3: =INDIRECT("B" & (4 + ($H3-1)*4)) -> (16) ONG JICKLE CLAIN | L3: =INDIRECT("B" & (5 + ($H3-1)*4)) -> 15 - 8
B4: (1) LARRAZABAL ALEXA | H4: 3 | I4: =INDIRECT("A" & (3 + ($H4-1)*4)) -> (9) VILLAPANDO JHOLAN DLSU / PHI | J4: =INDIRECT("A" & (5 + ($H4-1)*4)) -> (24) BERNABE FRANCESCA BETTINA ADMU / PHI | K4: =INDIRECT("B" & (4 + ($H4-1)*4)) -> (9) BERNABE FRANCESCA BETTINA | L4: =INDIRECT("B" & (5 + ($H4-1)*4)) -> 15 - 13
A5: (32) TRINIDAD SOLANA MAYUMI EZKRIMA / PHI | B5: 15 - 5 | H5: 4 | I5: =INDIRECT("A" & (3 + ($H5-1)*4)) -> (25) JIMENEZ JULIANNA UE / PHI | J5: =INDIRECT("A" & (5 + ($H5-1)*4)) -> (8) DINOY IVY CLAIRE MP / PHI | K5: =INDIRECT("B" & (4 + ($H5-1)*4)) -> (8) DINOY IVY CLAIRE | L5: =INDIRECT("B" & (5 + ($H5-1)*4)) -> 15 - 5
C6: (1) LARRAZABAL ALEXA | H6: 5 | I6: =INDIRECT("A" & (3 + ($H6-1)*4)) -> (5) VERGARA CYRRA DLSU / PHI | J6: =INDIRECT("A" & (5 + ($H6-1)*4)) -> (28) FELICIANO SUMMER LUCINE AF / PHI | K6: =INDIRECT("B" & (4 + ($H6-1)*4)) -> (5) VERGARA CYRRA | L6: =INDIRECT("B" & (5 + ($H6-1)*4)) -> 15 - 8
A7: (17) MANAOIS IRISH UE / PHI | C7: 15 - 9 12:17 PM | H7: 6 | I7: =INDIRECT("A" & (3 + ($H7-1)*4)) -> (21) BELEN FRANCES CAMILLE UP / PHI | J7: =INDIRECT("A" & (5 + ($H7-1)*4)) -> (12) MENDOZA JENNINA UP / PHI | K7: =INDIRECT("B" & (4 + ($H7-1)*4)) -> (12) MENDOZA JENNINA | L7: =INDIRECT("B" & (5 + ($H7-1)*4)) -> 15 - 2
B8: (16) ONG JICKLE CLAIN | H8: 7 | I8: =INDIRECT("A" & (3 + ($H8-1)*4)) -> (13) SALVADOR IVANA CF / PHI | J8: =INDIRECT("A" & (5 + ($H8-1)*4)) -> (20) NORO NAMI UP / PHI | K8: =INDIRECT("B" & (4 + ($H8-1)*4)) -> (13) NORO NAMI | L8: =INDIRECT("B" & (5 + ($H8-1)*4)) -> 15 - 8
A9: (16) ONG JICKLE CLAIN CF / PHI | B9: 15 - 8 | H9: 8 | I9: =INDIRECT("A" & (3 + ($H9-1)*4)) -> (29) RAFAEL GAY MARIE RF / PHI | J9: =INDIRECT("A" & (5 + ($H9-1)*4)) -> (4) BALLESTEROS JULIANNA UP / PHI | K9: =INDIRECT("B" & (4 + ($H9-1)*4)) -> (4) BALLESTEROS JULIANNA | L9: =INDIRECT("B" & (5 + ($H9-1)*4)) -> 15 - 9
D10: (1) LARRAZABAL ALEXA | H10: 9 | I10: =INDIRECT("A" & (3 + ($H10-1)*4)) -> (3) CANLAS NINA DOMINIQUE UE / PHI | J10: =INDIRECT("A" & (5 + ($H10-1)*4)) -> (30) UY JANA ANNIKA CF / PHI | K10: =INDIRECT("B" & (4 + ($H10-1)*4)) -> (3) CANLAS NINA DOMINIQUE | L10: =INDIRECT("B" & (5 + ($H10-1)*4)) -> 15 - 12
A11: (9) VILLAPANDO JHOLAN DLSU / PHI | D11: 15 - 12 12:56 PM | H11: 10 | I11: =INDIRECT("A" & (3 + ($H11-1)*4)) -> (19) RAGOT MIKAELA NICOLE UE / PHI | J11: =INDIRECT("A" & (5 + ($H11-1)*4)) -> (14) GOMEZ JULIANA MA. BEATRICE MP / PHI | K11: =INDIRECT("B" & (4 + ($H11-1)*4)) -> (14) GOMEZ JULIANA MA. BEATRICE | L11: =INDIRECT("B" & (5 + ($H11-1)*4)) -> 15 - 7
B12: (9) BERNABE FRANCESCA BETTINA | H12: 11 | I12: =INDIRECT("A" & (3 + ($H12-1)*4)) -> (11) BUSTOS MICKYLE REIN RF / PHI | J12: =INDIRECT("A" & (5 + ($H12-1)*4)) -> (22) EDNILAG KRUPS KAYA DLSU / PHI | K12: =INDIRECT("B" & (4 + ($H12-1)*4)) -> (11) BUSTOS MICKYLE REIN | L12: =INDIRECT("B" & (5 + ($H12-1)*4)) -> 15 - 11
A13: (24) BERNABE FRANCESCA BETTINA ADMU / PHI | B13: 15 - 13 | H13: 12 | I13: =INDIRECT("A" & (3 + ($H13-1)*4)) -> (27) TORRE PAPINA MARGUERITE AF / PHI | J13: =INDIRECT("A" & (5 + ($H13-1)*4)) -> (6) MATIAS ANDREA JENNELLE UE / PHI | K13: =INDIRECT("B" & (4 + ($H13-1)*4)) -> (6) MATIAS ANDREA JENNELLE | L13: =INDIRECT("B" & (5 + ($H13-1)*4)) -> 15 - 10
C14: (8) DINOY IVY CLAIRE | H14: 13 | I14: =INDIRECT("A" & (3 + ($H14-1)*4)) -> (7) HARRISON ASHLEY MAE MICHELLE NTP / PHI | J14: =INDIRECT("A" & (5 + ($H14-1)*4)) -> (26) JUNIA ELEINA MARGUERITE AF / PHI | K14: =INDIRECT("B" & (4 + ($H14-1)*4)) -> (7) HARRISON ASHLEY MAE MICHELLE | L14: =INDIRECT("B" & (5 + ($H14-1)*4)) -> 15 - 8
A15: (25) JIMENEZ JULIANNA UE / PHI | C15: 15 - 8 12:20 PM | H15: 14 | I15: =INDIRECT("A" & (3 + ($H15-1)*4)) -> (23) TAPALES ENDIRAJ MARGARET UP / PHI | J15: =INDIRECT("A" & (5 + ($H15-1)*4)) -> (10) SCHOFIELD CYRYLLE ANNE UE / PHI | K15: =INDIRECT("B" & (4 + ($H15-1)*4)) -> (10) TAPALES ENDIRAJ MARGARET | L15: =INDIRECT("B" & (5 + ($H15-1)*4)) -> 15 - 8
B16: (8) DINOY IVY CLAIRE | H16: 15 | I16: =INDIRECT("A" & (3 + ($H16-1)*4)) -> (15) DEL ROSARIO SARINA KELLY RF / PHI | J16: =INDIRECT("A" & (5 + ($H16-1)*4)) -> (18) DELOS SANTOS JAYMI NTP / PHI | K16: =INDIRECT("B" & (4 + ($H16-1)*4)) -> (15) DELOS SANTOS JAYMI | L16: =INDIRECT("B" & (5 + ($H16-1)*4)) -> 15 - 4
A17: (8) DINOY IVY CLAIRE MP / PHI | B17: 15 - 5 | H17: 16 | I17: =INDIRECT("A" & (3 + ($H17-1)*4)) -> (31) RAFAEL RANA IMOGEN ADMU / PHI | J17: =INDIRECT("A" & (5 + ($H17-1)*4)) -> (2) ABELLA HANNIEL NTP / PHI | K17: =INDIRECT("B" & (4 + ($H17-1)*4)) -> (2) ABELLA HANNIEL | L17: =INDIRECT("B" & (5 + ($H17-1)*4)) -> 15 - 5
E18: (1) LARRAZABAL ALEXA | H18: 1 | I18: =INDIRECT("B" & (4 + ($H18-1)*4)) -> (1) LARRAZABAL ALEXA | J18: =INDIRECT("B" & (8 + ($H18-1)*4)) -> (16) ONG JICKLE CLAIN | K18: =INDIRECT("C" & (6 + ($H18-1)*4)) -> (1) LARRAZABAL ALEXA | L18: =INDIRECT("C" & (7 + ($H18-1)*4)) -> 15 - 9 12:17 PM
A19: (5) VERGARA CYRRA DLSU / PHI | E19: 15 - 12 1:29 PM | H19: 3 | I19: =INDIRECT("B" & (4 + ($H19-1)*4)) -> (9) BERNABE FRANCESCA BETTINA | J19: =INDIRECT("B" & (8 + ($H19-1)*4)) -> (8) DINOY IVY CLAIRE | K19: =INDIRECT("C" & (6 + ($H19-1)*4)) -> (8) DINOY IVY CLAIRE | L19: =INDIRECT("C" & (7 + ($H19-1)*4)) -> 15 - 8 12:20 PM
B20: (5) VERGARA CYRRA | H20: 5 | I20: =INDIRECT("B" & (4 + ($H20-1)*4)) -> (5) VERGARA CYRRA | J20: =INDIRECT("B" & (8 + ($H20-1)*4)) -> (12) MENDOZA JENNINA | K20: =INDIRECT("C" & (6 + ($H20-1)*4)) -> (5) MENDOZA JENNINA | L20: =INDIRECT("C" & (7 + ($H20-1)*4)) -> 15 - 11 12:14 PM
A21: (28) FELICIANO SUMMER LUCINE AF / PHI | B21: 15 - 8 | H21: 7 | I21: =INDIRECT("B" & (4 + ($H21-1)*4)) -> (13) NORO NAMI | J21: =INDIRECT("B" & (8 + ($H21-1)*4)) -> (4) BALLESTEROS JULIANNA | K21: =INDIRECT("C" & (6 + ($H21-1)*4)) -> (4) BALLESTEROS JULIANNA | L21: =INDIRECT("C" & (7 + ($H21-1)*4)) -> 15 - 13 12:22 PM
C22: (5) MENDOZA JENNINA | H22: 9 | I22: =INDIRECT("B" & (4 + ($H22-1)*4)) -> (3) CANLAS NINA DOMINIQUE | J22: =INDIRECT("B" & (8 + ($H22-1)*4)) -> (14) GOMEZ JULIANA MA. BEATRICE | K22: =INDIRECT("C" & (6 + ($H22-1)*4)) -> (3) GOMEZ JULIANA MA. BEATRICE | L22: =INDIRECT("C" & (7 + ($H22-1)*4)) -> 15 - 14 12:32 PM
A23: (21) BELEN FRANCES CAMILLE UP / PHI | C23: 15 - 11 12:14 PM | H23: 11 | I23: =INDIRECT("B" & (4 + ($H23-1)*4)) -> (11) BUSTOS MICKYLE REIN | J23: =INDIRECT("B" & (8 + ($H23-1)*4)) -> (6) MATIAS ANDREA JENNELLE | K23: =INDIRECT("C" & (6 + ($H23-1)*4)) -> (6) MATIAS ANDREA JENNELLE | L23: =INDIRECT("C" & (7 + ($H23-1)*4)) -> 15 - 10 12:33 PM
B24: (12) MENDOZA JENNINA | H24: 13 | I24: =INDIRECT("B" & (4 + ($H24-1)*4)) -> (7) HARRISON ASHLEY MAE MICHELLE | J24: =INDIRECT("B" & (8 + ($H24-1)*4)) -> (10) TAPALES ENDIRAJ MARGARET | K24: =INDIRECT("C" & (6 + ($H24-1)*4)) -> (7) HARRISON ASHLEY MAE MICHELLE | L24: =INDIRECT("C" & (7 + ($H24-1)*4)) -> 14 - 11 12:36 PM
A25: (12) MENDOZA JENNINA UP / PHI | B25: 15 - 2 | H25: 15 | I25: =INDIRECT("B" & (4 + ($H25-1)*4)) -> (15) DELOS SANTOS JAYMI | J25: =INDIRECT("B" & (8 + ($H25-1)*4)) -> (2) ABELLA HANNIEL | K25: =INDIRECT("C" & (6 + ($H25-1)*4)) -> (2) DELOS SANTOS JAYMI | L25: =INDIRECT("C" & (7 + ($H25-1)*4)) -> 15 - 10 12:32 PM
D26: (4) MENDOZA JENNINA | H26: 1 | I26: =INDIRECT("C" & (6 + ($H26-1)*4)) -> (1) LARRAZABAL ALEXA | J26: =INDIRECT("C" & (14 + ($H26-1)*4)) -> (8) DINOY IVY CLAIRE | K26: =INDIRECT("D" & (10 + ($H26-1)*4)) -> (1) LARRAZABAL ALEXA | L26: =INDIRECT("D" & (11 + ($H26-1)*4)) -> 15 - 12 12:56 PM
A27: (13) SALVADOR IVANA CF / PHI | D27: 15 - 9 12:57 PM | H27: 5 | I27: =INDIRECT("C" & (6 + ($H27-1)*4)) -> (5) MENDOZA JENNINA | J27: =INDIRECT("C" & (14 + ($H27-1)*4)) -> (4) BALLESTEROS JULIANNA | K27: =INDIRECT("D" & (10 + ($H27-1)*4)) -> (4) MENDOZA JENNINA | L27: =INDIRECT("D" & (11 + ($H27-1)*4)) -> 15 - 9 12:57 PM
B28: (13) NORO NAMI | H28: 9 | I28: =INDIRECT("C" & (6 + ($H28-1)*4)) -> (3) GOMEZ JULIANA MA. BEATRICE | J28: =INDIRECT("C" & (14 + ($H28-1)*4)) -> (6) MATIAS ANDREA JENNELLE | K28: =INDIRECT("D" & (10 + ($H28-1)*4)) -> (3) GOMEZ JULIANA MA. BEATRICE | L28: =INDIRECT("D" & (11 + ($H28-1)*4)) -> 15 - 11 1:05 PM
A29: (20) NORO NAMI UP / PHI | B29: 15 - 8 | H29: 13 | I29: =INDIRECT("C" & (6 + ($H29-1)*4)) -> (7) HARRISON ASHLEY MAE MICHELLE | J29: =INDIRECT("C" & (14 + ($H29-1)*4)) -> (2) DELOS SANTOS JAYMI | K29: =INDIRECT("D" & (10 + ($H29-1)*4)) -> (2) HARRISON ASHLEY MAE MICHELLE | L29: =INDIRECT("D" & (11 + ($H29-1)*4)) -> 15 - 11 1:04 PM
C30: (4) BALLESTEROS JULIANNA | H30: 1 | I30: =INDIRECT("D" & (10 + ($H30-1)*4)) -> (1) LARRAZABAL ALEXA | J30: =INDIRECT("D" & (26 + ($H30-1)*4)) -> (4) MENDOZA JENNINA | K30: =INDIRECT("E" & (18 + ($H30-1)*4)) -> (1) LARRAZABAL ALEXA | L30: =INDIRECT("E" & (19 + ($H30-1)*4)) -> 15 - 12 1:29 PM
A31: (29) RAFAEL GAY MARIE RF / PHI | C31: 15 - 13 12:22 PM | H31: 9 | I31: =INDIRECT("D" & (10 + ($H31-1)*4)) -> (3) GOMEZ JULIANA MA. BEATRICE | J31: =INDIRECT("D" & (26 + ($H31-1)*4)) -> (2) HARRISON ASHLEY MAE MICHELLE | K31: =INDIRECT("E" & (18 + ($H31-1)*4)) -> (2) HARRISON ASHLEY MAE MICHELLE | L31: =INDIRECT("E" & (19 + ($H31-1)*4)) -> 15 - 13 1:28 PM
B32: (4) BALLESTEROS JULIANNA | H32: 1 | I32: {=INDIRECT("E" & (18 + ($H32-1)*4))} -> (1) LARRAZABAL ALEXA | J32: {=INDIRECT("E" & (50 + ($H32-1)*4))} -> (2) HARRISON ASHLEY MAE MICHELLE | K32: {=INDIRECT("F" & (34 + ($H32-1)*4))} -> (1) LARRAZABAL ALEXA | L32: {=INDIRECT("F" & (35 + ($H32-1)*4))} -> 15 - 13 1:47 PM
A33: (4) BALLESTEROS JULIANNA UP / PHI | B33: 15 - 9
F34: (1) LARRAZABAL ALEXA
A35: (3) CANLAS NINA DOMINIQUE UE / PHI | F35: 15 - 13 1:47 PM
B36: (3) CANLAS NINA DOMINIQUE
A37: (30) UY JANA ANNIKA CF / PHI | B37: 15 - 12
C38: (3) GOMEZ JULIANA MA. BEATRICE
A39: (19) RAGOT MIKAELA NICOLE UE / PHI | C39: 15 - 14 12:32 PM
B40: (14) GOMEZ JULIANA MA. BEATRICE
...

Sheet Leg 2
A1: Table of 64 | B1: Table of 32 | C1: Table of 16 | D1: Table of 8 | E1: Semi-Finals | F1: Finals | I1: right.fencer | J1: left.fencer | K1: winner | L1: score
H2: 1 | I2: =INDIRECT("A" & (3 + ($H2-1)*4)) -> (1) SEVILLA JULIANA SHANE MP / PHI | J2: =INDIRECT("A" & (5 + ($H2-1)*4)) -> (64) - BYE - | K2: =INDIRECT("B" & (4 + ($H2-1)*4)) -> (1) SEVILLA JULIANA SHANE | L2: =INDIRECT("B" & (5 + ($H2-1)*4)) -> 0
A3: (1) SEVILLA JULIANA SHANE MP / PHI | H3: 2 | I3: =INDIRECT("A" & (3 + ($H3-1)*4)) -> (33) SIA SARAH-INGRID AURELIA RF / PHI | J3: =INDIRECT("A" & (5 + ($H3-1)*4)) -> (32) CAPUNO DAHLIA MAE USTFT / PHI | K3: =INDIRECT("B" & (4 + ($H3-1)*4)) -> (32) CAPUNO DAHLIA MAE | L3: =INDIRECT("B" & (5 + ($H3-1)*4)) -> 15 - 14
B4: (1) SEVILLA JULIANA SHANE | H4: 3 | I4: =INDIRECT("A" & (3 + ($H4-1)*4)) -> (17) DELOS SANTOS JAYMI NTP / PHI | J4: =INDIRECT("A" & (5 + ($H4-1)*4)) -> (48) - BYE - | K4: =INDIRECT("B" & (4 + ($H4-1)*4)) -> (17) DELOS SANTOS JAYMI | L4: =INDIRECT("B" & (5 + ($H4-1)*4)) -> 0
A5: (64) - BYE - | H5: 4 | I5: =INDIRECT("A" & (3 + ($H5-1)*4)) -> (49) - BYE - | J5: =INDIRECT("A" & (5 + ($H5-1)*4)) -> (16) MENDOZA JENNINA UP / PHI | K5: =INDIRECT("B" & (4 + ($H5-1)*4)) -> (16) MENDOZA JENNINA | L5: =INDIRECT("B" & (5 + ($H5-1)*4)) -> 0
C6: (1) SEVILLA JULIANA SHANE | H6: 5 | I6: =INDIRECT("A" & (3 + ($H6-1)*4)) -> (9) EDNILAG KRUPS KAYA DLSU / PHI | J6: =INDIRECT("A" & (5 + ($H6-1)*4)) -> (56) - BYE - | K6: =INDIRECT("B" & (4 + ($H6-1)*4)) -> (9) EDNILAG KRUPS KAYA | L6: =INDIRECT("B" & (5 + ($H6-1)*4)) -> 0
A7: (33) SIA SARAH-INGRID AURELIA RF / PHI | C7: 13 - 7 12:17 PM | H7: 6 | I7: =INDIRECT("A" & (3 + ($H7-1)*4)) -> (41) - BYE - | J7: =INDIRECT("A" & (5 + ($H7-1)*4)) -> (24) SANDOVAL JUSTA ANDREA CF / PHI | K7: =INDIRECT("B" & (4 + ($H7-1)*4)) -> (24) SANDOVAL JUSTA ANDREA | L7: =INDIRECT("B" & (5 + ($H7-1)*4)) -> 0
B8: (32) CAPUNO DAHLIA MAE | H8: 7 | I8: =INDIRECT("A" & (3 + ($H8-1)*4)) -> (25) SALVADOR IVANA CF / PHI | J8: =INDIRECT("A" & (5 + ($H8-1)*4)) -> (40) - BYE - | K8: =INDIRECT("B" & (4 + ($H8-1)*4)) -> (25) SALVADOR IVANA | L8: =INDIRECT("B" & (5 + ($H8-1)*4)) -> 0
A9: (32) CAPUNO DAHLIA MAE USTFT / PHI | B9: 15 - 14 | H9: 8 | I9: =INDIRECT("A" & (3 + ($H9-1)*4)) -> (57) - BYE - | J9: =INDIRECT("A" & (5 + ($H9-1)*4)) -> (8) TAPALES ENDIRAJ MARGARET UP / PHI | K9: =INDIRECT("B" & (4 + ($H9-1)*4)) -> (8) TAPALES ENDIRAJ MARGARET | L9: =INDIRECT("B" & (5 + ($H9-1)*4)) -> 0
D10: (1) DELOS SANTOS JAYMI | H10: 9 | I10: =INDIRECT("A" & (3 + ($H10-1)*4)) -> (5) MATIAS ANDREA JENNELLE UE / PHI | J10: =INDIRECT("A" & (5 + ($H10-1)*4)) -> (60) - BYE - | K10: =INDIRECT("B" & (4 + ($H10-1)*4)) -> (5) MATIAS ANDREA JENNELLE | L10: =INDIRECT("B" & (5 + ($H10-1)*4)) -> 0
A11: (17) DELOS SANTOS JAYMI NTP / PHI | D11: 15 - 7 12:50 PM | H11: 10 | I11: =INDIRECT("A" & (3 + ($H11-1)*4)) -> (37) - BYE - | J11: =INDIRECT("A" & (5 + ($H11-1)*4)) -> (28) TORRE PAPINA MARGUERITE AF / PHI | K11: =INDIRECT("B" & (4 + ($H11-1)*4)) -> (28) TORRE PAPINA MARGUERITE | L11: =INDIRECT("B" & (5 + ($H11-1)*4)) -> 0
B12: (17) DELOS SANTOS JAYMI | H12: 11 | I12: =INDIRECT("A" & (3 + ($H12-1)*4)) -> (21) DELA CRUZ CHIARA MICHAELA UPFC / PHI | J12: =INDIRECT("A" & (5 + ($H12-1)*4)) -> (44) - BYE - | K12: =INDIRECT("B" & (4 + ($H12-1)*4)) -> (21) DELA CRUZ CHIARA MICHAELA | L12: =INDIRECT("B" & (5 + ($H12-1)*4)) -> 0
A13: (48) - BYE - | H13: 12 | I13: =INDIRECT("A" & (3 + ($H13-1)*4)) -> (53) - BYE - | J13: =INDIRECT("A" & (5 + ($H13-1)*4)) -> (12) SCHOFIELD CYRYLLE ANNE UE / PHI | K13: =INDIRECT("B" & (4 + ($H13-1)*4)) -> (12) SCHOFIELD CYRYLLE ANNE | L13: =INDIRECT("B" & (5 + ($H13-1)*4)) -> 0
C14: (16) DELOS SANTOS JAYMI | H14: 13 | I14: =INDIRECT("A" & (3 + ($H14-1)*4)) -> (13) TRINIDAD SOLANA MAYUMI EZKRIMA / PHI | J14: =INDIRECT("A" & (5 + ($H14-1)*4)) -> (52) - BYE - | K14: =INDIRECT("B" & (4 + ($H14-1)*4)) -> (13) TRINIDAD SOLANA MAYUMI | L14: =INDIRECT("B" & (5 + ($H14-1)*4)) -> 0
A15: (49) - BYE - | C15: 15 - 10 | H15: 14 | I15: =INDIRECT("A" & (3 + ($H15-1)*4)) -> (45) - BYE - | J15: =INDIRECT("A" & (5 + ($H15-1)*4)) -> (20) RAGOT MIKAELA NICOLE UE / PHI | K15: =INDIRECT("B" & (4 + ($H15-1)*4)) -> (20) RAGOT MIKAELA NICOLE | L15: =INDIRECT("B" & (5 + ($H15-1)*4)) -> 0
B16: (16) MENDOZA JENNINA | H16: 15 | I16: =INDIRECT("A" & (3 + ($H16-1)*4)) -> (29) JUNIA ELEINA MARGUERITE AF / PHI | J16: =INDIRECT("A" & (5 + ($H16-1)*4)) -> (36) PALO AJ DREYFUS ADMU / PHI | K16: =INDIRECT("B" & (4 + ($H16-1)*4)) -> (29) JUNIA ELEINA MARGUERITE | L16: =INDIRECT("B" & (5 + ($H16-1)*4)) -> 15 - 13
A17: (16) MENDOZA JENNINA UP / PHI | H17: 16 | I17: =INDIRECT("A" & (3 + ($H17-1)*4)) -> (61) - BYE - | J17: =INDIRECT("A" & (5 + ($H17-1)*4)) -> (4) GOMEZ JULIANA MA. BEATRICE MP / PHI | K17: =INDIRECT("B" & (4 + ($H17-1)*4)) -> (4) GOMEZ JULIANA MA. BEATRICE | L17: =INDIRECT("B" & (5 + ($H17-1)*4)) -> 0
E18: (1) EDNILAG KRUPS KAYA | H18: 17 | I18: =INDIRECT("A" & (3 + ($H18-1)*4)) -> (3) ABELLA HANNIEL NTP / PHI | J18: =INDIRECT("A" & (5 + ($H18-1)*4)) -> (62) - BYE - | K18: =INDIRECT("B" & (4 + ($H18-1)*4)) -> (3) ABELLA HANNIEL | L18: =INDIRECT("B" & (5 + ($H18-1)*4)) -> 0
A19: (9) EDNILAG KRUPS KAYA DLSU / PHI | E19: 15 - 10 1:37 PM | H19: 18 | I19: =INDIRECT("A" & (3 + ($H19-1)*4)) -> (35) FELICIANO SUMMER LUCINE AF / PHI | J19: =INDIRECT("A" & (5 + ($H19-1)*4)) -> (30) GEPUELA CATHERINE THERESE UP / PHI | K19: =INDIRECT("B" & (4 + ($H19-1)*4)) -> (30) GEPUELA CATHERINE THERESE | L19: =INDIRECT("B" & (5 + ($H19-1)*4)) -> 11 - 10
B20: (9) EDNILAG KRUPS KAYA | H20: 19 | I20: =INDIRECT("A" & (3 + ($H20-1)*4)) -> (19) FLORES MARIEL ELIANNE UP / PHI | J20: =INDIRECT("A" & (5 + ($H20-1)*4)) -> (46) - BYE - | K20: =INDIRECT("B" & (4 + ($H20-1)*4)) -> (19) FLORES MARIEL ELIANNE | L20: =INDIRECT("B" & (5 + ($H20-1)*4)) -> 0
A21: (56) - BYE - | H21: 20 | I21: =INDIRECT("A" & (3 + ($H21-1)*4)) -> (51) - BYE - | J21: =INDIRECT("A" & (5 + ($H21-1)*4)) -> (14) VILLAPANDO JHOLAN DLSU / PHI | K21: =INDIRECT("B" & (4 + ($H21-1)*4)) -> (14) VILLAPANDO JHOLAN | L21: =INDIRECT("B" & (5 + ($H21-1)*4)) -> 0
C22: (9) EDNILAG KRUPS KAYA | H22: 21 | I22: =INDIRECT("A" & (3 + ($H22-1)*4)) -> (11) DINOY IVY CLAIRE MP / PHI | J22: =INDIRECT("A" & (5 + ($H22-1)*4)) -> (54) - BYE - | K22: =INDIRECT("B" & (4 + ($H22-1)*4)) -> (11) DINOY IVY CLAIRE | L22: =INDIRECT("B" & (5 + ($H22-1)*4)) -> 0
A23: (41) - BYE - | C23: 15 - 11 | H23: 22 | I23: =INDIRECT("A" & (3 + ($H23-1)*4)) -> (43) - BYE - | J23: =INDIRECT("A" & (5 + ($H23-1)*4)) -> (22) NORO NAMI UP / PHI | K23: =INDIRECT("B" & (4 + ($H23-1)*4)) -> (22) NORO NAMI | L23: =INDIRECT("B" & (5 + ($H23-1)*4)) -> 0
B24: (24) SANDOVAL JUSTA ANDREA | H24: 23 | I24: =INDIRECT("A" & (3 + ($H24-1)*4)) -> (27) MANAOIS IRISH UE / PHI | J24: =INDIRECT("A" & (5 + ($H24-1)*4)) -> (38) - BYE - | K24: =INDIRECT("B" & (4 + ($H24-1)*4)) -> (27) MANAOIS IRISH | L24: =INDIRECT("B" & (5 + ($H24-1)*4)) -> 0
A25: (24) SANDOVAL JUSTA ANDREA CF / PHI | H25: 24 | I25: =INDIRECT("A" & (3 + ($H25-1)*4)) -> (59) - BYE - | J25: =INDIRECT("A" & (5 + ($H25-1)*4)) -> (6) HARRISON ASHLEY MAE MICHELLE NTP / PHI | K25: =INDIRECT("B" & (4 + ($H25-1)*4)) -> (6) HARRISON ASHLEY MAE MICHELLE | L25: =INDIRECT("B" & (5 + ($H25-1)*4)) -> 0
D26: (8) EDNILAG KRUPS KAYA | H26: 25 | I26: =INDIRECT("A" & (3 + ($H26-1)*4)) -> (7) LARRAZABAL ALEXA NTP / PHI | J26: =INDIRECT("A" & (5 + ($H26-1)*4)) -> (58) - BYE - | K26: =INDIRECT("B" & (4 + ($H26-1)*4)) -> (7) LARRAZABAL ALEXA | L26: =INDIRECT("B" & (5 + ($H26-1)*4)) -> 0
A27: (25) SALVADOR IVANA CF / PHI | D27: 15 - 11 12:48 PM | H27: 26 | I27: =INDIRECT("A" & (3 + ($H27-1)*4)) -> (39) - BYE - | J27: =INDIRECT("A" & (5 + ($H27-1)*4)) -> (26) SYKAT ROBYN NOELLE RF / PHI | K27: =INDIRECT("B" & (4 + ($H27-1)*4)) -> (26) SYKAT ROBYN NOELLE | L27: =INDIRECT("B" & (5 + ($H27-1)*4)) -> 0
B28: (25) SALVADOR IVANA | H28: 27 | I28: =INDIRECT("A" & (3 + ($H28-1)*4)) -> (23) MARTINEZ TASHA ISABELLA HCFC / PHI | J28: =INDIRECT("A" & (5 + ($H28-1)*4)) -> (42) - BYE - | K28: =INDIRECT("B" & (4 + ($H28-1)*4)) -> (23) MARTINEZ TASHA ISABELLA | L28: =INDIRECT("B" & (5 + ($H28-1)*4)) -> 0
A29: (40) - BYE - | H29: 28 | I29: =INDIRECT("A" & (3 + ($H29-1)*4)) -> (55) - BYE - | J29: =INDIRECT("A" & (5 + ($H29-1)*4)) -> (10) BUSTOS MICKYLE REIN RF / PHI | K29: =INDIRECT("B" & (4 + ($H29-1)*4)) -> (10) BUSTOS MICKYLE REIN | L29: =INDIRECT("B" & (5 + ($H29-1)*4)) -> 0
C30: (8) SALVADOR IVANA | H30: 29 | I30: =INDIRECT("A" & (3 + ($H30-1)*4)) -> (15) ONG JICKLE CLAIN CF / PHI | J30: =INDIRECT("A" & (5 + ($H30-1)*4)) -> (50) - BYE - | K30: =INDIRECT("B" & (4 + ($H30-1)*4)) -> (15) ONG JICKLE CLAIN | L30: =INDIRECT("B" & (5 + ($H30-1)*4)) -> 0
A31: (57) - BYE - | C31: 12 - 11 | H31: 30 | I31: =INDIRECT("A" & (3 + ($H31-1)*4)) -> (47) - BYE - | J31: =INDIRECT("A" & (5 + ($H31-1)*4)) -> (18) VERGARA CYRRA DLSU / PHI | K31: =INDIRECT("B" & (4 + ($H31-1)*4)) -> (18) VERGARA CYRRA | L31: =INDIRECT("B" & (5 + ($H31-1)*4)) -> 0
B32: (8) TAPALES ENDIRAJ MARGARET | H32: 31 | I32: =INDIRECT("A" & (3 + ($H32-1)*4)) -> (31) BUENO MARIA KRISTINA ANGELA CF / PHI | J32: =INDIRECT("A" & (5 + ($H32-1)*4)) -> (34) LOPEZ ALTHEA SOPHIA USTFT / PHI | K32: =INDIRECT("B" & (4 + ($H32-1)*4)) -> (31) BUENO MARIA KRISTINA ANGELA | L32: =INDIRECT("B" & (5 + ($H32-1)*4)) -> 15 - 12
A33: (8) TAPALES ENDIRAJ MARGARET UP / PHI | H33: 32 | I33: =INDIRECT("A" & (3 + ($H33-1)*4)) -> (63) - BYE - | J33: =INDIRECT("A" & (5 + ($H33-1)*4)) -> (2) CANLAS NINA DOMINIQUE UE / PHI | K33: =INDIRECT("B" & (4 + ($H33-1)*4)) -> (2) CANLAS NINA DOMINIQUE | L33: =INDIRECT("B" & (5 + ($H33-1)*4)) -> 0
F34: (1) EDNILAG KRUPS KAYA | H34: 1 | I34: =INDIRECT("B" & (4 + ($H34-1)*4)) -> (1) SEVILLA JULIANA SHANE | J34: =INDIRECT("B" & (8 + ($H34-1)*4)) -> (32) CAPUNO DAHLIA MAE | K34: =INDIRECT("C" & (6 + ($H34-1)*4)) -> (1) SEVILLA JULIANA SHANE | L34: =INDIRECT("C" & (7 + ($H34-1)*4)) -> 13 - 7 12:17 PM
A35: (5) MATIAS ANDREA JENNELLE UE / PHI | F35: 15 - 9 2:06 PM | H35: 3 | I35: =INDIRECT("B" & (4 + ($H35-1)*4)) -> (17) DELOS SANTOS JAYMI | J35: =INDIRECT("B" & (8 + ($H35-1)*4)) -> (16) MENDOZA JENNINA | K35: =INDIRECT("C" & (6 + ($H35-1)*4)) -> (16) DELOS SANTOS JAYMI | L35: =INDIRECT("C" & (7 + ($H35-1)*4)) -> 15 - 10
B36: (5) MATIAS ANDREA JENNELLE | H36: 5 | I36: =INDIRECT("B" & (4 + ($H36-1)*4)) -> (9) EDNILAG KRUPS KAYA | J36: =INDIRECT("B" & (8 + ($H36-1)*4)) -> (24) SANDOVAL JUSTA ANDREA | K36: =INDIRECT("C" & (6 + ($H36-1)*4)) -> (9) EDNILAG KRUPS KAYA | L36: =INDIRECT("C" & (7 + ($H36-1)*4)) -> 15 - 11
A37: (60) - BYE - | H37: 7 | I37: =INDIRECT("B" & (4 + ($H37-1)*4)) -> (25) SALVADOR IVANA | J37: =INDIRECT("B" & (8 + ($H37-1)*4)) -> (8) TAPALES ENDIRAJ MARGARET | K37: =INDIRECT("C" & (6 + ($H37-1)*4)) -> (8) SALVADOR IVANA | L37: =INDIRECT("C" & (7 + ($H37-1)*4)) -> 12 - 11
C38: (5) MATIAS ANDREA JENNELLE | H38: 9 | I38: =INDIRECT("B" & (4 + ($H38-1)*4)) -> (5) MATIAS ANDREA JENNELLE | J38: =INDIRECT("B" & (8 + ($H38-1)*4)) -> (28) TORRE PAPINA MARGUERITE | K38: =INDIRECT("C" & (6 + ($H38-1)*4)) -> (5) MATIAS ANDREA JENNELLE | L38: =INDIRECT("C" & (7 + ($H38-1)*4)) -> 15 - 6
A39: (37) - BYE - | C39: 15 - 6 | H39: 11 | I39: =INDIRECT("B" & (4 + ($H39-1)*4)) -> (21) DELA CRUZ CHIARA MICHAELA | J39: =INDIRECT("B" & (8 + ($H39-1)*4)) -> (12) SCHOFIELD CYRYLLE ANNE | K39: =INDIRECT("C" & (6 + ($H39-1)*4)) -> (12) SCHOFIELD CYRYLLE ANNE | L39: =INDIRECT("C" & (7 + ($H39-1)*4)) -> 15 - 10
B40: (28) TORRE PAPINA MARGUERITE | H40: 13 | I40: =INDIRECT("B" & (4 + ($H40-1)*4)) -> (13) TRINIDAD SOLANA MAYUMI | J40: =INDIRECT("B" & (8 + ($H40-1)*4)) -> (20) RAGOT MIKAELA NICOLE | K40: =INDIRECT("C" & (6 + ($H40-1)*4)) -> (13) TRINIDAD SOLANA MAYUMI | L40: =INDIRECT("C" & (7 + ($H40-1)*4)) -> 15 - 9
...

Sheet Leg 3
A1: Table of 32 | B1: Table of 16 | C1: Table of 8 | D1: Semi-Finals | E1: Finals | I1: right.fencer | J1: left.fencer | K1: winner | L1: score
H2: 1 | I2: =INDIRECT("A" & (3 + ($H2-1)*4)) -> (1) LARRAZABAL ALEXA NTP / PHI | J2: =INDIRECT("A" & (5 + ($H2-1)*4)) -> (32) SIA SARAH-INGRID AURELIA RF / PHI | K2: =INDIRECT("B" & (4 + ($H2-1)*4)) -> (1) LARRAZABAL ALEXA | L2: =INDIRECT("B" & (5 + ($H2-1)*4)) -> 15 - 4
A3: (1) LARRAZABAL ALEXA NTP / PHI | H3: 2 | I3: =INDIRECT("A" & (3 + ($H3-1)*4)) -> (17) ONG JICKLE CLAIN CF / PHI | J3: =INDIRECT("A" & (5 + ($H3-1)*4)) -> (16) MANAOIS IRISH UE / PHI | K3: =INDIRECT("B" & (4 + ($H3-1)*4)) -> (16) ONG JICKLE CLAIN | L3: =INDIRECT("B" & (5 + ($H3-1)*4)) -> 15 - 14
B4: (1) LARRAZABAL ALEXA | H4: 3 | I4: =INDIRECT("A" & (3 + ($H4-1)*4)) -> (9) TRINIDAD SOLANA MAYUMI EZKRIMA / PHI | J4: =INDIRECT("A" & (5 + ($H4-1)*4)) -> (24) GEPUELA CATHERINE THERESE UP / PHI | K4: =INDIRECT("B" & (4 + ($H4-1)*4)) -> (9) TRINIDAD SOLANA MAYUMI | L4: =INDIRECT("B" & (5 + ($H4-1)*4)) -> 15 - 13
A5: (32) SIA SARAH-INGRID AURELIA RF / PHI | B5: 15 - 4 | H5: 4 | I5: =INDIRECT("A" & (3 + ($H5-1)*4)) -> (25) BARRIENTOS ANDREA HCFC / PHI | J5: =INDIRECT("A" & (5 + ($H5-1)*4)) -> (8) HARRISON ASHLEY MAE MICHELLE NTP / PHI | K5: =INDIRECT("B" & (4 + ($H5-1)*4)) -> (8) HARRISON ASHLEY MAE MICHELLE | L5: =INDIRECT("B" & (5 + ($H5-1)*4)) -> 15 - 3
C6: (1) LARRAZABAL ALEXA | H6: 5 | I6: =INDIRECT("A" & (3 + ($H6-1)*4)) -> (5) SCHOFIELD CYRYLLE ANNE UE / PHI | J6: =INDIRECT("A" & (5 + ($H6-1)*4)) -> (28) SANDOVAL JUSTA ANDREA CF / PHI | K6: =INDIRECT("B" & (4 + ($H6-1)*4)) -> (5) SCHOFIELD CYRYLLE ANNE | L6: =INDIRECT("B" & (5 + ($H6-1)*4)) -> 15 - 11
A7: (17) ONG JICKLE CLAIN CF / PHI | C7: 15 - 13 11:45 AM | H7: 6 | I7: =INDIRECT("A" & (3 + ($H7-1)*4)) -> (21) TORRE PAPINA MARGUERITE AF / PHI | J7: =INDIRECT("A" & (5 + ($H7-1)*4)) -> (12) BUSTOS MICKYLE REIN RF / PHI | K7: =INDIRECT("B" & (4 + ($H7-1)*4)) -> (12) BUSTOS MICKYLE REIN | L7: =INDIRECT("B" & (5 + ($H7-1)*4)) -> 15 - 6
B8: (16) ONG JICKLE CLAIN | H8: 7 | I8: =INDIRECT("A" & (3 + ($H8-1)*4)) -> (13) CANLAS NINA DOMINIQUE UE / PHI | J8: =INDIRECT("A" & (5 + ($H8-1)*4)) -> (20) SYKAT ROBYN NOELLE RF / PHI | K8: =INDIRECT("B" & (4 + ($H8-1)*4)) -> (13) CANLAS NINA DOMINIQUE | L8: =INDIRECT("B" & (5 + ($H8-1)*4)) -> 15 - 8
A9: (16) MANAOIS IRISH UE / PHI | B9: 15 - 14 | H9: 8 | I9: =INDIRECT("A" & (3 + ($H9-1)*4)) -> (29) DELA CRUZ CHIARA MICHAELA UPFC / PHI | J9: =INDIRECT("A" & (5 + ($H9-1)*4)) -> (4) ABELLA HANNIEL NTP / PHI | K9: =INDIRECT("B" & (4 + ($H9-1)*4)) -> (4) ABELLA HANNIEL | L9: =INDIRECT("B" & (5 + ($H9-1)*4)) -> 15 - 7
D10: (1) LARRAZABAL ALEXA | H10: 9 | I10: =INDIRECT("A" & (3 + ($H10-1)*4)) -> (3) GOMEZ JULIANA MA. BEATRICE MP / PHI | J10: =INDIRECT("A" & (5 + ($H10-1)*4)) -> (30) TAPALES ENDIRAJ MARGARET UP / PHI | K10: =INDIRECT("B" & (4 + ($H10-1)*4)) -> (3) GOMEZ JULIANA MA. BEATRICE | L10: =INDIRECT("B" & (5 + ($H10-1)*4)) -> 15 - 14
A11: (9) TRINIDAD SOLANA MAYUMI EZKRIMA / PHI | D11: 15 - 8 12:49 PM | H11: 10 | I11: =INDIRECT("A" & (3 + ($H11-1)*4)) -> (19) NORO NAMI UP / PHI | J11: =INDIRECT("A" & (5 + ($H11-1)*4)) -> (14) RAGOT MIKAELA NICOLE UE / PHI | K11: =INDIRECT("B" & (4 + ($H11-1)*4)) -> (14) NORO NAMI | L11: =INDIRECT("B" & (5 + ($H11-1)*4)) -> 15 - 9
B12: (9) TRINIDAD SOLANA MAYUMI | H12: 11 | I12: =INDIRECT("A" & (3 + ($H12-1)*4)) -> (11) DELOS SANTOS JAYMI NTP / PHI | J12: =INDIRECT("A" & (5 + ($H12-1)*4)) -> (22) BUENO MARIA KRISTINA ANGELA CF / PHI | K12: =INDIRECT("B" & (4 + ($H12-1)*4)) -> (11) BUENO MARIA KRISTINA ANGELA | L12: =INDIRECT("B" & (5 + ($H12-1)*4)) -> 15 - 14
A13: (24) GEPUELA CATHERINE THERESE UP / PHI | B13: 15 - 13 | H13: 12 | I13: =INDIRECT("A" & (3 + ($H13-1)*4)) -> (27) MARTINEZ TASHA ISABELLA HCFC / PHI | J13: =INDIRECT("A" & (5 + ($H13-1)*4)) -> (6) VERGARA CYRRA DLSU / PHI | K13: =INDIRECT("B" & (4 + ($H13-1)*4)) -> (6) VERGARA CYRRA | L13: =INDIRECT("B" & (5 + ($H13-1)*4)) -> 15 - 12
C14: (8) HARRISON ASHLEY MAE MICHELLE | H14: 13 | I14: =INDIRECT("A" & (3 + ($H14-1)*4)) -> (7) SALVADOR IVANA CF / PHI | J14: =INDIRECT("A" & (5 + ($H14-1)*4)) -> (26) FELICIANO SUMMER LUCINE AF / PHI | K14: =INDIRECT("B" & (4 + ($H14-1)*4)) -> (7) SALVADOR IVANA | L14: =INDIRECT("B" & (5 + ($H14-1)*4)) -> 15 - 3
A15: (25) BARRIENTOS ANDREA HCFC / PHI | C15: 15 - 6 11:54 AM | H15: 14 | I15: =INDIRECT("A" & (3 + ($H15-1)*4)) -> (23) FLORES MARIEL ELIANNE UP / PHI | J15: =INDIRECT("A" & (5 + ($H15-1)*4)) -> (10) EDNILAG KRUPS KAYA DLSU / PHI | K15: =INDIRECT("B" & (4 + ($H15-1)*4)) -> (10) EDNILAG KRUPS KAYA | L15: =INDIRECT("B" & (5 + ($H15-1)*4)) -> 15 - 11
B16: (8) HARRISON ASHLEY MAE MICHELLE | H16: 15 | I16: =INDIRECT("A" & (3 + ($H16-1)*4)) -> (15) MATIAS ANDREA JENNELLE UE / PHI | J16: =INDIRECT("A" & (5 + ($H16-1)*4)) -> (18) MENDOZA JENNINA UP / PHI | K16: =INDIRECT("B" & (4 + ($H16-1)*4)) -> (15) MATIAS ANDREA JENNELLE | L16: =INDIRECT("B" & (5 + ($H16-1)*4)) -> 15 - 12
A17: (8) HARRISON ASHLEY MAE MICHELLE NTP / PHI | B17: 15 - 3 | H17: 16 | I17: =INDIRECT("A" & (3 + ($H17-1)*4)) -> (31) JUNIA ELEINA MARGUERITE AF / PHI | J17: =INDIRECT("A" & (5 + ($H17-1)*4)) -> (2) DINOY IVY CLAIRE MP / PHI | K17: =INDIRECT("B" & (4 + ($H17-1)*4)) -> (2) DINOY IVY CLAIRE | L17: =INDIRECT("B" & (5 + ($H17-1)*4)) -> 15 - 5
E18: (1) ABELLA HANNIEL | H18: 1 | I18: =INDIRECT("B" & (4 + ($H18-1)*4)) -> (1) LARRAZABAL ALEXA | J18: =INDIRECT("B" & (8 + ($H18-1)*4)) -> (16) ONG JICKLE CLAIN | K18: =INDIRECT("C" & (6 + ($H18-1)*4)) -> (1) LARRAZABAL ALEXA | L18: =INDIRECT("C" & (7 + ($H18-1)*4)) -> 15 - 13 11:45 AM
A19: (5) SCHOFIELD CYRYLLE ANNE UE / PHI | E19: 15 - 12 1:17 PM | H19: 3 | I19: =INDIRECT("B" & (4 + ($H19-1)*4)) -> (9) TRINIDAD SOLANA MAYUMI | J19: =INDIRECT("B" & (8 + ($H19-1)*4)) -> (8) HARRISON ASHLEY MAE MICHELLE | K19: =INDIRECT("C" & (6 + ($H19-1)*4)) -> (8) HARRISON ASHLEY MAE MICHELLE | L19: =INDIRECT("C" & (7 + ($H19-1)*4)) -> 15 - 6 11:54 AM
B20: (5) SCHOFIELD CYRYLLE ANNE | H20: 5 | I20: =INDIRECT("B" & (4 + ($H20-1)*4)) -> (5) SCHOFIELD CYRYLLE ANNE | J20: =INDIRECT("B" & (8 + ($H20-1)*4)) -> (12) BUSTOS MICKYLE REIN | K20: =INDIRECT("C" & (6 + ($H20-1)*4)) -> (5) BUSTOS MICKYLE REIN | L20: =INDIRECT("C" & (7 + ($H20-1)*4)) -> 15 - 9 11:47 AM
A21: (28) SANDOVAL JUSTA ANDREA CF / PHI | B21: 15 - 11 | H21: 7 | I21: =INDIRECT("B" & (4 + ($H21-1)*4)) -> (13) CANLAS NINA DOMINIQUE | J21: =INDIRECT("B" & (8 + ($H21-1)*4)) -> (4) ABELLA HANNIEL | K21: =INDIRECT("C" & (6 + ($H21-1)*4)) -> (4) ABELLA HANNIEL | L21: =INDIRECT("C" & (7 + ($H21-1)*4)) -> 15 - 9 11:52 AM
C22: (5) BUSTOS MICKYLE REIN | H22: 9 | I22: =INDIRECT("B" & (4 + ($H22-1)*4)) -> (3) GOMEZ JULIANA MA. BEATRICE | J22: =INDIRECT("B" & (8 + ($H22-1)*4)) -> (14) NORO NAMI | K22: =INDIRECT("C" & (6 + ($H22-1)*4)) -> (3) GOMEZ JULIANA MA. BEATRICE | L22: =INDIRECT("C" & (7 + ($H22-1)*4)) -> 15 - 7 12:16 PM
A23: (21) TORRE PAPINA MARGUERITE AF / PHI | C23: 15 - 9 11:47 AM | H23: 11 | I23: =INDIRECT("B" & (4 + ($H23-1)*4)) -> (11) BUENO MARIA KRISTINA ANGELA | J23: =INDIRECT("B" & (8 + ($H23-1)*4)) -> (6) VERGARA CYRRA | K23: =INDIRECT("C" & (6 + ($H23-1)*4)) -> (6) VERGARA CYRRA | L23: =INDIRECT("C" & (7 + ($H23-1)*4)) -> 15 - 10 12:14 PM
B24: (12) BUSTOS MICKYLE REIN | H24: 13 | I24: =INDIRECT("B" & (4 + ($H24-1)*4)) -> (7) SALVADOR IVANA | J24: =INDIRECT("B" & (8 + ($H24-1)*4)) -> (10) EDNILAG KRUPS KAYA | K24: =INDIRECT("C" & (6 + ($H24-1)*4)) -> (7) SALVADOR IVANA | L24: =INDIRECT("C" & (7 + ($H24-1)*4)) -> 15 - 10 12:12 PM
A25: (12) BUSTOS MICKYLE REIN RF / PHI | B25: 15 - 6 | H25: 15 | I25: =INDIRECT("B" & (4 + ($H25-1)*4)) -> (15) MATIAS ANDREA JENNELLE | J25: =INDIRECT("B" & (8 + ($H25-1)*4)) -> (2) DINOY IVY CLAIRE | K25: =INDIRECT("C" & (6 + ($H25-1)*4)) -> (2) DINOY IVY CLAIRE | L25: =INDIRECT("C" & (7 + ($H25-1)*4)) -> 15 - 8 12:14 PM
D26: (4) ABELLA HANNIEL | H26: 1 | I26: =INDIRECT("C" & (6 + ($H26-1)*4)) -> (1) LARRAZABAL ALEXA | J26: =INDIRECT("C" & (14 + ($H26-1)*4)) -> (8) HARRISON ASHLEY MAE MICHELLE | K26: =INDIRECT("D" & (10 + ($H26-1)*4)) -> (1) LARRAZABAL ALEXA | L26: =INDIRECT("D" & (11 + ($H26-1)*4)) -> 15 - 8 12:49 PM
A27: (13) CANLAS NINA DOMINIQUE UE / PHI | D27: 15 - 11 12:47 PM | H27: 5 | I27: =INDIRECT("C" & (6 + ($H27-1)*4)) -> (5) BUSTOS MICKYLE REIN | J27: =INDIRECT("C" & (14 + ($H27-1)*4)) -> (4) ABELLA HANNIEL | K27: =INDIRECT("D" & (10 + ($H27-1)*4)) -> (4) ABELLA HANNIEL | L27: =INDIRECT("D" & (11 + ($H27-1)*4)) -> 15 - 11 12:47 PM
B28: (13) CANLAS NINA DOMINIQUE | H28: 9 | I28: =INDIRECT("C" & (6 + ($H28-1)*4)) -> (3) GOMEZ JULIANA MA. BEATRICE | J28: =INDIRECT("C" & (14 + ($H28-1)*4)) -> (6) VERGARA CYRRA | K28: =INDIRECT("D" & (10 + ($H28-1)*4)) -> (3) GOMEZ JULIANA MA. BEATRICE | L28: =INDIRECT("D" & (11 + ($H28-1)*4)) -> 15 - 14 12:50 PM
A29: (20) SYKAT ROBYN NOELLE RF / PHI | B29: 15 - 8 | H29: 13 | I29: =INDIRECT("C" & (6 + ($H29-1)*4)) -> (7) SALVADOR IVANA | J29: =INDIRECT("C" & (14 + ($H29-1)*4)) -> (2) DINOY IVY CLAIRE | K29: =INDIRECT("D" & (10 + ($H29-1)*4)) -> (2) DINOY IVY CLAIRE | L29: =INDIRECT("D" & (11 + ($H29-1)*4)) -> 15 - 1 12:49 PM
C30: (4) ABELLA HANNIEL | H30: 1 | I30: =INDIRECT("D" & (10 + ($H30-1)*4)) -> (1) LARRAZABAL ALEXA | J30: =INDIRECT("D" & (26 + ($H30-1)*4)) -> (4) ABELLA HANNIEL | K30: =INDIRECT("E" & (18 + ($H30-1)*4)) -> (1) ABELLA HANNIEL | L30: =INDIRECT("E" & (19 + ($H30-1)*4)) -> 15 - 12 1:17 PM
A31: (29) DELA CRUZ CHIARA MICHAELA UPFC / PHI | C31: 15 - 9 11:52 AM | H31: 9 | I31: =INDIRECT("D" & (10 + ($H31-1)*4)) -> (3) GOMEZ JULIANA MA. BEATRICE | J31: =INDIRECT("D" & (26 + ($H31-1)*4)) -> (2) DINOY IVY CLAIRE | K31: =INDIRECT("E" & (18 + ($H31-1)*4)) -> (2) DINOY IVY CLAIRE | L31: =INDIRECT("E" & (19 + ($H31-1)*4)) -> 12 - 11 1:15 PM
B32: (4) ABELLA HANNIEL | H32: 1 | I32: {=INDIRECT("E" & (18 + ($H32-1)*4))} -> (1) ABELLA HANNIEL | J32: {=INDIRECT("E" & (50 + ($H32-1)*4))} -> (2) DINOY IVY CLAIRE | K32: {=INDIRECT("F" & (34 + ($H32-1)*4))} -> (1) DINOY IVY CLAIRE | L32: {=INDIRECT("F" & (35 + ($H32-1)*4))} -> 12 - 6 1:46 PM Strip F
A33: (4) ABELLA HANNIEL NTP / PHI | B33: 15 - 7
F34: (1) DINOY IVY CLAIRE
A35: (3) GOMEZ JULIANA MA. BEATRICE MP / PHI | F35: 12 - 6 1:46 PM Strip F
B36: (3) GOMEZ JULIANA MA. BEATRICE
A37: (30) TAPALES ENDIRAJ MARGARET UP / PHI | B37: 15 - 14
C38: (3) GOMEZ JULIANA MA. BEATRICE
A39: (19) NORO NAMI UP / PHI | C39: 15 - 7 12:16 PM
B40: (14) NORO NAMI
...

Sheet Leg 4
A1: Table of 32 | B1: Table of 16 | C1: Table of 8 | D1: Semi-Finals | E1: Finals | I1: right.fencer | J1: left.fencer | K1: winner | L1: score
H2: 1 | I2: =INDIRECT("A" & (3 + ($H2-1)*4)) -> (1) DINOY IVY CLAIRE PMPA / PHI | J2: =INDIRECT("A" & (5 + ($H2-1)*4)) -> (32) - BYE - | K2: =INDIRECT("B" & (4 + ($H2-1)*4)) -> (1) DINOY IVY CLAIRE | L2: =INDIRECT("B" & (5 + ($H2-1)*4)) -> 0
A3: (1) DINOY IVY CLAIRE PMPA / PHI | H3: 2 | I3: =INDIRECT("A" & (3 + ($H3-1)*4)) -> (17) BUENO MARIA KRISTINA ANGELA CF / PHI | J3: =INDIRECT("A" & (5 + ($H3-1)*4)) -> (16) BUSTOS MICKYLE REIN RF / PHI | K3: =INDIRECT("B" & (4 + ($H3-1)*4)) -> (16) BUSTOS MICKYLE REIN | L3: =INDIRECT("B" & (5 + ($H3-1)*4)) -> 15 - 6
B4: (1) DINOY IVY CLAIRE | H4: 3 | I4: =INDIRECT("A" & (3 + ($H4-1)*4)) -> (9) TAPALES ENDIRAJ MARGARET UP / PHI | J4: =INDIRECT("A" & (5 + ($H4-1)*4)) -> (24) TORRE PAPINA MARGUERITE AF / PHI | K4: =INDIRECT("B" & (4 + ($H4-1)*4)) -> (9) TAPALES ENDIRAJ MARGARET | L4: =INDIRECT("B" & (5 + ($H4-1)*4)) -> 15 - 12
A5: (32) - BYE - | H5: 4 | I5: =INDIRECT("A" & (3 + ($H5-1)*4)) -> (25) SYKAT ROBYN NOELLE RF / PHI | J5: =INDIRECT("A" & (5 + ($H5-1)*4)) -> (8) SANDOVAL JUSTA ANDREA CF / PHI | K5: =INDIRECT("B" & (4 + ($H5-1)*4)) -> (8) SYKAT ROBYN NOELLE | L5: =INDIRECT("B" & (5 + ($H5-1)*4)) -> 15 - 14
C6: (1) DINOY IVY CLAIRE | H6: 5 | I6: =INDIRECT("A" & (3 + ($H6-1)*4)) -> (5) ABELLA HANNIEL NTP / PHI | J6: =INDIRECT("A" & (5 + ($H6-1)*4)) -> (28) RAFAEL GAY MARIE RF / PHI | K6: =INDIRECT("B" & (4 + ($H6-1)*4)) -> (5) ABELLA HANNIEL | L6: =INDIRECT("B" & (5 + ($H6-1)*4)) -> 15 - 4
A7: (17) BUENO MARIA KRISTINA ANGELA CF / PHI | C7: 15 - 9 11:47 AM | H7: 6 | I7: =INDIRECT("A" & (3 + ($H7-1)*4)) -> (21) JUNIA ELEINA MARGUERITE AF / PHI | J7: =INDIRECT("A" & (5 + ($H7-1)*4)) -> (12) SALVADOR IVANA CF / PHI | K7: =INDIRECT("B" & (4 + ($H7-1)*4)) -> (12) SALVADOR IVANA | L7: =INDIRECT("B" & (5 + ($H7-1)*4)) -> 15 - 6
B8: (16) BUSTOS MICKYLE REIN | H8: 7 | I8: =INDIRECT("A" & (3 + ($H8-1)*4)) -> (13) VILLAPANDO JHOLAN DLSU / PHI | J8: =INDIRECT("A" & (5 + ($H8-1)*4)) -> (20) NORO NAMI UP / PHI | K8: =INDIRECT("B" & (4 + ($H8-1)*4)) -> (13) NORO NAMI | L8: =INDIRECT("B" & (5 + ($H8-1)*4)) -> 15 - 14
A9: (16) BUSTOS MICKYLE REIN RF / PHI | B9: 15 - 6 | H9: 8 | I9: =INDIRECT("A" & (3 + ($H9-1)*4)) -> (29) SIA SARAH-INGRID AURELIA RF / PHI | J9: =INDIRECT("A" & (5 + ($H9-1)*4)) -> (4) HARRISON ASHLEY MAE MICHELLE NTP / PHI | K9: =INDIRECT("B" & (4 + ($H9-1)*4)) -> (4) HARRISON ASHLEY MAE MICHELLE | L9: =INDIRECT("B" & (5 + ($H9-1)*4)) -> 15 - 5
D10: (1) DINOY IVY CLAIRE | H10: 9 | I10: =INDIRECT("A" & (3 + ($H10-1)*4)) -> (3) MATIAS ANDREA JENNELLE UE / PHI | J10: =INDIRECT("A" & (5 + ($H10-1)*4)) -> (30) MANAOIS IRISH UE / PHI | K10: =INDIRECT("B" & (4 + ($H10-1)*4)) -> (3) MATIAS ANDREA JENNELLE | L10: =INDIRECT("B" & (5 + ($H10-1)*4)) -> 15 - 11
A11: (9) TAPALES ENDIRAJ MARGARET UP / PHI | D11: 15 - 8 12:50 PM | H11: 10 | I11: =INDIRECT("A" & (3 + ($H11-1)*4)) -> (19) CAPINA MIYAKE DLSZ / PHI | J11: =INDIRECT("A" & (5 + ($H11-1)*4)) -> (14) MENDOZA JENNINA UP / PHI | K11: =INDIRECT("B" & (4 + ($H11-1)*4)) -> (14) MENDOZA JENNINA | L11: =INDIRECT("B" & (5 + ($H11-1)*4)) -> 15 - 13
B12: (9) TAPALES ENDIRAJ MARGARET | H12: 11 | I12: =INDIRECT("A" & (3 + ($H12-1)*4)) -> (11) DELOS SANTOS JAYMI NTP / PHI | J12: =INDIRECT("A" & (5 + ($H12-1)*4)) -> (22) FLORES MARIEL ELIANNE UP / PHI | K12: =INDIRECT("B" & (4 + ($H12-1)*4)) -> (11) DELOS SANTOS JAYMI | L12: =INDIRECT("B" & (5 + ($H12-1)*4)) -> 15 - 14
A13: (24) TORRE PAPINA MARGUERITE AF / PHI | B13: 15 - 12 | H13: 12 | I13: =INDIRECT("A" & (3 + ($H13-1)*4)) -> (27) RAGOT MIKAELA NICOLE UE / PHI | J13: =INDIRECT("A" & (5 + ($H13-1)*4)) -> (6) CANLAS NINA DOMINIQUE UE / PHI | K13: =INDIRECT("B" & (4 + ($H13-1)*4)) -> (6) CANLAS NINA DOMINIQUE | L13: =INDIRECT("B" & (5 + ($H13-1)*4)) -> 15 - 13
C14: (8) SYKAT ROBYN NOELLE | H14: 13 | I14: =INDIRECT("A" & (3 + ($H14-1)*4)) -> (7) GOMEZ JULIANA MA. BEATRICE PMPA / PHI | J14: =INDIRECT("A" & (5 + ($H14-1)*4)) -> (26) DEL ROSARIO SARINA KELLY RF / PHI | K14: =INDIRECT("B" & (4 + ($H14-1)*4)) -> (7) GOMEZ JULIANA MA. BEATRICE | L14: =INDIRECT("B" & (5 + ($H14-1)*4)) -> 15 - 6
A15: (25) SYKAT ROBYN NOELLE RF / PHI | C15: 15 - 10 11:58 AM | H15: 14 | I15: =INDIRECT("A" & (3 + ($H15-1)*4)) -> (23) EDNILAG KRUPSKAYA DLSU / PHI | J15: =INDIRECT("A" & (5 + ($H15-1)*4)) -> (10) RAFAEL RANA IMOGEN ADMU/RF / PHI | K15: =INDIRECT("B" & (4 + ($H15-1)*4)) -> (10) EDNILAG KRUPSKAYA | L15: =INDIRECT("B" & (5 + ($H15-1)*4)) -> 15 - 13
B16: (8) SYKAT ROBYN NOELLE | H16: 15 | I16: =INDIRECT("A" & (3 + ($H16-1)*4)) -> (15) UY JANA ANNIKA CF / PHI | J16: =INDIRECT("A" & (5 + ($H16-1)*4)) -> (18) BACCAY MARTINA JENE DLSZ / PHI | K16: =INDIRECT("B" & (4 + ($H16-1)*4)) -> (15) UY JANA ANNIKA | L16: =INDIRECT("B" & (5 + ($H16-1)*4)) -> 15 - 11
A17: (8) SANDOVAL JUSTA ANDREA CF / PHI | B17: 15 - 14 | H17: 16 | I17: =INDIRECT("A" & (3 + ($H17-1)*4)) -> (31) MANGULABNAN KIANA DOMINIQUE UPFC / PHI | J17: =INDIRECT("A" & (5 + ($H17-1)*4)) -> (2) LARRAZABAL ALEXA NTP / PHI | K17: =INDIRECT("B" & (4 + ($H17-1)*4)) -> (2) LARRAZABAL ALEXA | L17: =INDIRECT("B" & (5 + ($H17-1)*4)) -> 15 - 3
E18: (1) ABELLA HANNIEL | H18: 1 | I18: =INDIRECT("B" & (4 + ($H18-1)*4)) -> (1) DINOY IVY CLAIRE | J18: =INDIRECT("B" & (8 + ($H18-1)*4)) -> (16) BUSTOS MICKYLE REIN | K18: =INDIRECT("C" & (6 + ($H18-1)*4)) -> (1) DINOY IVY CLAIRE | L18: =INDIRECT("C" & (7 + ($H18-1)*4)) -> 15 - 9 11:47 AM
A19: (5) ABELLA HANNIEL NTP / PHI | E19: 13 - 12 1:25 PM | H19: 3 | I19: =INDIRECT("B" & (4 + ($H19-1)*4)) -> (9) TAPALES ENDIRAJ MARGARET | J19: =INDIRECT("B" & (8 + ($H19-1)*4)) -> (8) SYKAT ROBYN NOELLE | K19: =INDIRECT("C" & (6 + ($H19-1)*4)) -> (8) SYKAT ROBYN NOELLE | L19: =INDIRECT("C" & (7 + ($H19-1)*4)) -> 15 - 10 11:58 AM
B20: (5) ABELLA HANNIEL | H20: 5 | I20: =INDIRECT("B" & (4 + ($H20-1)*4)) -> (5) ABELLA HANNIEL | J20: =INDIRECT("B" & (8 + ($H20-1)*4)) -> (12) SALVADOR IVANA | K20: =INDIRECT("C" & (6 + ($H20-1)*4)) -> (5) ABELLA HANNIEL | L20: =INDIRECT("C" & (7 + ($H20-1)*4)) -> 15 - 10 11:50 AM
A21: (28) RAFAEL GAY MARIE RF / PHI | B21: 15 - 4 | H21: 7 | I21: =INDIRECT("B" & (4 + ($H21-1)*4)) -> (13) NORO NAMI | J21: =INDIRECT("B" & (8 + ($H21-1)*4)) -> (4) HARRISON ASHLEY MAE MICHELLE | K21: =INDIRECT("C" & (6 + ($H21-1)*4)) -> (4) HARRISON ASHLEY MAE MICHELLE | L21: =INDIRECT("C" & (7 + ($H21-1)*4)) -> 15 - 7 11:53 AM
C22: (5) ABELLA HANNIEL | H22: 9 | I22: =INDIRECT("B" & (4 + ($H22-1)*4)) -> (3) MATIAS ANDREA JENNELLE | J22: =INDIRECT("B" & (8 + ($H22-1)*4)) -> (14) MENDOZA JENNINA | K22: =INDIRECT("C" & (6 + ($H22-1)*4)) -> (3) MATIAS ANDREA JENNELLE | L22: =INDIRECT("C" & (7 + ($H22-1)*4)) -> 15 - 11 12:16 PM
A23: (21) JUNIA ELEINA MARGUERITE AF / PHI | C23: 15 - 10 11:50 AM | H23: 11 | I23: =INDIRECT("B" & (4 + ($H23-1)*4)) -> (11) DELOS SANTOS JAYMI | J23: =INDIRECT("B" & (8 + ($H23-1)*4)) -> (6) CANLAS NINA DOMINIQUE | K23: =INDIRECT("C" & (6 + ($H23-1)*4)) -> (6) DELOS SANTOS JAYMI | L23: =INDIRECT("C" & (7 + ($H23-1)*4)) -> 15 - 12 12:19 PM
B24: (12) SALVADOR IVANA | H24: 13 | I24: =INDIRECT("B" & (4 + ($H24-1)*4)) -> (7) GOMEZ JULIANA MA. BEATRICE | J24: =INDIRECT("B" & (8 + ($H24-1)*4)) -> (10) EDNILAG KRUPSKAYA | K24: =INDIRECT("C" & (6 + ($H24-1)*4)) -> (7) GOMEZ JULIANA MA. BEATRICE | L24: =INDIRECT("C" & (7 + ($H24-1)*4)) -> 15 - 5 12:17 PM
A25: (12) SALVADOR IVANA CF / PHI | B25: 15 - 6 | H25: 15 | I25: =INDIRECT("B" & (4 + ($H25-1)*4)) -> (15) UY JANA ANNIKA | J25: =INDIRECT("B" & (8 + ($H25-1)*4)) -> (2) LARRAZABAL ALEXA | K25: =INDIRECT("C" & (6 + ($H25-1)*4)) -> (2) LARRAZABAL ALEXA | L25: =INDIRECT("C" & (7 + ($H25-1)*4)) -> 15 - 8 12:21 PM
D26: (4) ABELLA HANNIEL | H26: 1 | I26: =INDIRECT("C" & (6 + ($H26-1)*4)) -> (1) DINOY IVY CLAIRE | J26: =INDIRECT("C" & (14 + ($H26-1)*4)) -> (8) SYKAT ROBYN NOELLE | K26: =INDIRECT("D" & (10 + ($H26-1)*4)) -> (1) DINOY IVY CLAIRE | L26: =INDIRECT("D" & (11 + ($H26-1)*4)) -> 15 - 8 12:50 PM
A27: (13) VILLAPANDO JHOLAN DLSU / PHI | D27: 15 - 9 12:49 PM | H27: 5 | I27: =INDIRECT("C" & (6 + ($H27-1)*4)) -> (5) ABELLA HANNIEL | J27: =INDIRECT("C" & (14 + ($H27-1)*4)) -> (4) HARRISON ASHLEY MAE MICHELLE | K27: =INDIRECT("D" & (10 + ($H27-1)*4)) -> (4) ABELLA HANNIEL | L27: =INDIRECT("D" & (11 + ($H27-1)*4)) -> 15 - 9 12:49 PM
B28: (13) NORO NAMI | H28: 9 | I28: =INDIRECT("C" & (6 + ($H28-1)*4)) -> (3) MATIAS ANDREA JENNELLE | J28: =INDIRECT("C" & (14 + ($H28-1)*4)) -> (6) DELOS SANTOS JAYMI | K28: =INDIRECT("D" & (10 + ($H28-1)*4)) -> (3) DELOS SANTOS JAYMI | L28: =INDIRECT("D" & (11 + ($H28-1)*4)) -> 15 - 10 12:47 PM
A29: (20) NORO NAMI UP / PHI | B29: 15 - 14 | H29: 13 | I29: =INDIRECT("C" & (6 + ($H29-1)*4)) -> (7) GOMEZ JULIANA MA. BEATRICE | J29: =INDIRECT("C" & (14 + ($H29-1)*4)) -> (2) LARRAZABAL ALEXA | K29: =INDIRECT("D" & (10 + ($H29-1)*4)) -> (2) LARRAZABAL ALEXA | L29: =INDIRECT("D" & (11 + ($H29-1)*4)) -> 15 - 7 12:43 PM
C30: (4) HARRISON ASHLEY MAE MICHELLE | H30: 1 | I30: =INDIRECT("D" & (10 + ($H30-1)*4)) -> (1) DINOY IVY CLAIRE | J30: =INDIRECT("D" & (26 + ($H30-1)*4)) -> (4) ABELLA HANNIEL | K30: =INDIRECT("E" & (18 + ($H30-1)*4)) -> (1) ABELLA HANNIEL | L30: =INDIRECT("E" & (19 + ($H30-1)*4)) -> 13 - 12 1:25 PM
A31: (29) SIA SARAH-INGRID AURELIA RF / PHI | C31: 15 - 7 11:53 AM | H31: 9 | I31: =INDIRECT("D" & (10 + ($H31-1)*4)) -> (3) DELOS SANTOS JAYMI | J31: =INDIRECT("D" & (26 + ($H31-1)*4)) -> (2) LARRAZABAL ALEXA | K31: =INDIRECT("E" & (18 + ($H31-1)*4)) -> (2) LARRAZABAL ALEXA | L31: =INDIRECT("E" & (19 + ($H31-1)*4)) -> 15 - 10 1:22 PM
B32: (4) HARRISON ASHLEY MAE MICHELLE | H32: 1 | I32: {=INDIRECT("E" & (18 + ($H32-1)*4))} -> (1) ABELLA HANNIEL | J32: {=INDIRECT("E" & (50 + ($H32-1)*4))} -> (2) LARRAZABAL ALEXA | K32: {=INDIRECT("F" & (34 + ($H32-1)*4))} -> (1) LARRAZABAL ALEXA | L32: {=INDIRECT("F" & (35 + ($H32-1)*4))} -> 15 - 10 2:02 PM
A33: (4) HARRISON ASHLEY MAE MICHELLE NTP / PHI | B33: 15 - 5
F34: (1) LARRAZABAL ALEXA
A35: (3) MATIAS ANDREA JENNELLE UE / PHI | F35: 15 - 10 2:02 PM
B36: (3) MATIAS ANDREA JENNELLE
A37: (30) MANAOIS IRISH UE / PHI | B37: 15 - 11
C38: (3) MATIAS ANDREA JENNELLE
A39: (19) CAPINA MIYAKE DLSZ / PHI | C39: 15 - 11 12:16 PM
B40: (14) MENDOZA JENNINA
...

Sheet Leg 5
A1: Table of 32 | B1: Table of 16 | C1: Table of 8 | D1: Semi-Finals | E1: Finals | I1: right.fencer | J1: left.fencer | K1: winner | L1: score
H2: 1 | I2: =INDIRECT("A" & (3 + ($H2-1)*4)) -> (1) ABELLA HANNIEL NTP / PHI | J2: =INDIRECT("A" & (5 + ($H2-1)*4)) -> (32) - BYE - | K2: =INDIRECT("B" & (4 + ($H2-1)*4)) -> (1) ABELLA HANNIEL | L2: =INDIRECT("B" & (5 + ($H2-1)*4)) -> 0
A3: (1) ABELLA HANNIEL NTP / PHI | H3: 2 | I3: =INDIRECT("A" & (3 + ($H3-1)*4)) -> (17) FLORES MARIEL ELIANNE FRANCESCA UP / PHI | J3: =INDIRECT("A" & (5 + ($H3-1)*4)) -> (16) ONG JICKLE CLAIN CF / PHI | K3: =INDIRECT("B" & (4 + ($H3-1)*4)) -> (16) FLORES MARIEL ELIANNE FRANCESCA | L3: =INDIRECT("B" & (5 + ($H3-1)*4)) -> 15 - 9
B4: (1) ABELLA HANNIEL | H4: 3 | I4: =INDIRECT("A" & (3 + ($H4-1)*4)) -> (9) DELOS SANTOS JAYMI NTP / PHI | J4: =INDIRECT("A" & (5 + ($H4-1)*4)) -> (24) SALVADOR IVANA CF / PHI | K4: =INDIRECT("B" & (4 + ($H4-1)*4)) -> (9) DELOS SANTOS JAYMI | L4: =INDIRECT("B" & (5 + ($H4-1)*4)) -> 14 - 13
A5: (32) - BYE - | H5: 4 | I5: =INDIRECT("A" & (3 + ($H5-1)*4)) -> (25) UY JANA ANNIKA CF / PHI | J5: =INDIRECT("A" & (5 + ($H5-1)*4)) -> (8) MARTINEZ TASHA ISABELLA HCFC / PHI | K5: =INDIRECT("B" & (4 + ($H5-1)*4)) -> (8) UY JANA ANNIKA | L5: =INDIRECT("B" & (5 + ($H5-1)*4)) -> 15 - 11
C6: (1) ABELLA HANNIEL | H6: 5 | I6: =INDIRECT("A" & (3 + ($H6-1)*4)) -> (5) HARRISON ASHLEY MAE MICHELLE NTP / PHI | J6: =INDIRECT("A" & (5 + ($H6-1)*4)) -> (28) - BYE - | K6: =INDIRECT("B" & (4 + ($H6-1)*4)) -> (5) HARRISON ASHLEY MAE MICHELLE | L6: =INDIRECT("B" & (5 + ($H6-1)*4)) -> 0
A7: (17) FLORES MARIEL ELIANNE FRANCESCA UP / PHI | C7: 15 - 9 11:15 AM | H7: 6 | I7: =INDIRECT("A" & (3 + ($H7-1)*4)) -> (21) ASIS JUZ LOVAINE PMPA / PHI | J7: =INDIRECT("A" & (5 + ($H7-1)*4)) -> (12) MATIAS ANDREA JENNELLE UE / PHI | K7: =INDIRECT("B" & (4 + ($H7-1)*4)) -> (12) MATIAS ANDREA JENNELLE | L7: =INDIRECT("B" & (5 + ($H7-1)*4)) -> 15 - 11
B8: (16) FLORES MARIEL ELIANNE FRANCESCA | H8: 7 | I8: =INDIRECT("A" & (3 + ($H8-1)*4)) -> (13) EDNILAG KRUPSKAYA DLSU / PHI | J8: =INDIRECT("A" & (5 + ($H8-1)*4)) -> (20) RAFAEL RANA IMOGEN ADMU/RF / PHI | K8: =INDIRECT("B" & (4 + ($H8-1)*4)) -> (13) EDNILAG KRUPSKAYA | L8: =INDIRECT("B" & (5 + ($H8-1)*4)) -> 15 - 10
A9: (16) ONG JICKLE CLAIN CF / PHI | B9: 15 - 9 | H9: 8 | I9: =INDIRECT("A" & (3 + ($H9-1)*4)) -> (29) - BYE - | J9: =INDIRECT("A" & (5 + ($H9-1)*4)) -> (4) GOMEZ JULIANA MA. BEATRICE PMPA / PHI | K9: =INDIRECT("B" & (4 + ($H9-1)*4)) -> (4) GOMEZ JULIANA MA. BEATRICE | L9: =INDIRECT("B" & (5 + ($H9-1)*4)) -> 0
D10: (1) ABELLA HANNIEL | H10: 9 | I10: =INDIRECT("A" & (3 + ($H10-1)*4)) -> (3) LARRAZABAL ALEXA NTP / PHI | J10: =INDIRECT("A" & (5 + ($H10-1)*4)) -> (30) - BYE - | K10: =INDIRECT("B" & (4 + ($H10-1)*4)) -> (3) LARRAZABAL ALEXA | L10: =INDIRECT("B" & (5 + ($H10-1)*4)) -> 0
A11: (9) DELOS SANTOS JAYMI NTP / PHI | D11: 15 - 11 12:02 PM | H11: 10 | I11: =INDIRECT("A" & (3 + ($H11-1)*4)) -> (19) BACCAY MARTINA JENE DLSZ / PHI | J11: =INDIRECT("A" & (5 + ($H11-1)*4)) -> (14) MENDOZA JENNINA UP / PHI | K11: =INDIRECT("B" & (4 + ($H11-1)*4)) -> (14) MENDOZA JENNINA | L11: =INDIRECT("B" & (5 + ($H11-1)*4)) -> 15 - 2
B12: (9) DELOS SANTOS JAYMI | H12: 11 | I12: =INDIRECT("A" & (3 + ($H12-1)*4)) -> (11) TRINIDAD SOLANA MAYUMI EZKRIMA / PHI | J12: =INDIRECT("A" & (5 + ($H12-1)*4)) -> (22) CAPINA MIYAKE DLSZ / PHI | K12: =INDIRECT("B" & (4 + ($H12-1)*4)) -> (11) TRINIDAD SOLANA MAYUMI | L12: =INDIRECT("B" & (5 + ($H12-1)*4)) -> 15 - 8
A13: (24) SALVADOR IVANA CF / PHI | B13: 14 - 13 | H13: 12 | I13: =INDIRECT("A" & (3 + ($H13-1)*4)) -> (27) - BYE - | J13: =INDIRECT("A" & (5 + ($H13-1)*4)) -> (6) SANDOVAL JUSTA ANDREA CF / PHI | K13: =INDIRECT("B" & (4 + ($H13-1)*4)) -> (6) SANDOVAL JUSTA ANDREA | L13: =INDIRECT("B" & (5 + ($H13-1)*4)) -> 0
C14: (8) DELOS SANTOS JAYMI | H14: 13 | I14: =INDIRECT("A" & (3 + ($H14-1)*4)) -> (7) BUSTOS MICKYLE REIN RF / PHI | J14: =INDIRECT("A" & (5 + ($H14-1)*4)) -> (26) - BYE - | K14: =INDIRECT("B" & (4 + ($H14-1)*4)) -> (7) BUSTOS MICKYLE REIN | L14: =INDIRECT("B" & (5 + ($H14-1)*4)) -> 0
A15: (25) UY JANA ANNIKA CF / PHI | C15: 15 - 13 11:23 AM | H15: 14 | I15: =INDIRECT("A" & (3 + ($H15-1)*4)) -> (23) CARIG SOPHIA OF / PHI | J15: =INDIRECT("A" & (5 + ($H15-1)*4)) -> (10) CANLAS NINA DOMINIQUE UE / PHI | K15: =INDIRECT("B" & (4 + ($H15-1)*4)) -> (10) CANLAS NINA DOMINIQUE | L15: =INDIRECT("B" & (5 + ($H15-1)*4)) -> 15 - 9
B16: (8) UY JANA ANNIKA | H16: 15 | I16: =INDIRECT("A" & (3 + ($H16-1)*4)) -> (15) TORRE PAPINA MARGUERITE AF / PHI | J16: =INDIRECT("A" & (5 + ($H16-1)*4)) -> (18) SYKAT ROBYN NOELLE RF / PHI | K16: =INDIRECT("B" & (4 + ($H16-1)*4)) -> (15) TORRE PAPINA MARGUERITE | L16: =INDIRECT("B" & (5 + ($H16-1)*4)) -> 11 - 10
A17: (8) MARTINEZ TASHA ISABELLA HCFC / PHI | B17: 15 - 11 | H17: 16 | I17: =INDIRECT("A" & (3 + ($H17-1)*4)) -> (31) - BYE - | J17: =INDIRECT("A" & (5 + ($H17-1)*4)) -> (2) DINOY IVY CLAIRE PMPA / PHI | K17: =INDIRECT("B" & (4 + ($H17-1)*4)) -> (2) DINOY IVY CLAIRE | L17: =INDIRECT("B" & (5 + ($H17-1)*4)) -> 0
E18: (1) ABELLA HANNIEL | H18: 1 | I18: =INDIRECT("B" & (4 + ($H18-1)*4)) -> (1) ABELLA HANNIEL | J18: =INDIRECT("B" & (8 + ($H18-1)*4)) -> (16) FLORES MARIEL ELIANNE FRANCESCA | K18: =INDIRECT("C" & (6 + ($H18-1)*4)) -> (1) ABELLA HANNIEL | L18: =INDIRECT("C" & (7 + ($H18-1)*4)) -> 15 - 9 11:15 AM
A19: (5) HARRISON ASHLEY MAE MICHELLE NTP / PHI | E19: 15 - 11 12:38 PM | H19: 3 | I19: =INDIRECT("B" & (4 + ($H19-1)*4)) -> (9) DELOS SANTOS JAYMI | J19: =INDIRECT("B" & (8 + ($H19-1)*4)) -> (8) UY JANA ANNIKA | K19: =INDIRECT("C" & (6 + ($H19-1)*4)) -> (8) DELOS SANTOS JAYMI | L19: =INDIRECT("C" & (7 + ($H19-1)*4)) -> 15 - 13 11:23 AM
B20: (5) HARRISON ASHLEY MAE MICHELLE | H20: 5 | I20: =INDIRECT("B" & (4 + ($H20-1)*4)) -> (5) HARRISON ASHLEY MAE MICHELLE | J20: =INDIRECT("B" & (8 + ($H20-1)*4)) -> (12) MATIAS ANDREA JENNELLE | K20: =INDIRECT("C" & (6 + ($H20-1)*4)) -> (5) HARRISON ASHLEY MAE MICHELLE | L20: =INDIRECT("C" & (7 + ($H20-1)*4)) -> 15 - 12 11:21 AM
A21: (28) - BYE - | H21: 7 | I21: =INDIRECT("B" & (4 + ($H21-1)*4)) -> (13) EDNILAG KRUPSKAYA | J21: =INDIRECT("B" & (8 + ($H21-1)*4)) -> (4) GOMEZ JULIANA MA. BEATRICE | K21: =INDIRECT("C" & (6 + ($H21-1)*4)) -> (4) GOMEZ JULIANA MA. BEATRICE | L21: =INDIRECT("C" & (7 + ($H21-1)*4)) -> 15 - 7 11:15 AM
C22: (5) HARRISON ASHLEY MAE MICHELLE | H22: 9 | I22: =INDIRECT("B" & (4 + ($H22-1)*4)) -> (3) LARRAZABAL ALEXA | J22: =INDIRECT("B" & (8 + ($H22-1)*4)) -> (14) MENDOZA JENNINA | K22: =INDIRECT("C" & (6 + ($H22-1)*4)) -> (3) LARRAZABAL ALEXA | L22: =INDIRECT("C" & (7 + ($H22-1)*4)) -> 15 - 7 11:21 AM
A23: (21) ASIS JUZ LOVAINE PMPA / PHI | C23: 15 - 12 11:21 AM | H23: 11 | I23: =INDIRECT("B" & (4 + ($H23-1)*4)) -> (11) TRINIDAD SOLANA MAYUMI | J23: =INDIRECT("B" & (8 + ($H23-1)*4)) -> (6) SANDOVAL JUSTA ANDREA | K23: =INDIRECT("C" & (6 + ($H23-1)*4)) -> (6) TRINIDAD SOLANA MAYUMI | L23: =INDIRECT("C" & (7 + ($H23-1)*4)) -> 13 - 7 11:18 AM
B24: (12) MATIAS ANDREA JENNELLE | H24: 13 | I24: =INDIRECT("B" & (4 + ($H24-1)*4)) -> (7) BUSTOS MICKYLE REIN | J24: =INDIRECT("B" & (8 + ($H24-1)*4)) -> (10) CANLAS NINA DOMINIQUE | K24: =INDIRECT("C" & (6 + ($H24-1)*4)) -> (7) BUSTOS MICKYLE REIN | L24: =INDIRECT("C" & (7 + ($H24-1)*4)) -> 15 - 11 11:17 AM
A25: (12) MATIAS ANDREA JENNELLE UE / PHI | B25: 15 - 11 | H25: 15 | I25: =INDIRECT("B" & (4 + ($H25-1)*4)) -> (15) TORRE PAPINA MARGUERITE | J25: =INDIRECT("B" & (8 + ($H25-1)*4)) -> (2) DINOY IVY CLAIRE | K25: =INDIRECT("C" & (6 + ($H25-1)*4)) -> (2) DINOY IVY CLAIRE | L25: =INDIRECT("C" & (7 + ($H25-1)*4)) -> 15 - 4 11:38 AM
D26: (4) GOMEZ JULIANA MA. BEATRICE | H26: 1 | I26: =INDIRECT("C" & (6 + ($H26-1)*4)) -> (1) ABELLA HANNIEL | J26: =INDIRECT("C" & (14 + ($H26-1)*4)) -> (8) DELOS SANTOS JAYMI | K26: =INDIRECT("D" & (10 + ($H26-1)*4)) -> (1) ABELLA HANNIEL | L26: =INDIRECT("D" & (11 + ($H26-1)*4)) -> 15 - 11 12:02 PM
A27: (13) EDNILAG KRUPSKAYA DLSU / PHI | D27: 12 - 11 12:03 PM | H27: 5 | I27: =INDIRECT("C" & (6 + ($H27-1)*4)) -> (5) HARRISON ASHLEY MAE MICHELLE | J27: =INDIRECT("C" & (14 + ($H27-1)*4)) -> (4) GOMEZ JULIANA MA. BEATRICE | K27: =INDIRECT("D" & (10 + ($H27-1)*4)) -> (4) GOMEZ JULIANA MA. BEATRICE | L27: =INDIRECT("D" & (11 + ($H27-1)*4)) -> 12 - 11 12:03 PM
B28: (13) EDNILAG KRUPSKAYA | H28: 9 | I28: =INDIRECT("C" & (6 + ($H28-1)*4)) -> (3) LARRAZABAL ALEXA | J28: =INDIRECT("C" & (14 + ($H28-1)*4)) -> (6) TRINIDAD SOLANA MAYUMI | K28: =INDIRECT("D" & (10 + ($H28-1)*4)) -> (3) LARRAZABAL ALEXA | L28: =INDIRECT("D" & (11 + ($H28-1)*4)) -> 15 - 8 12:03 PM
A29: (20) RAFAEL RANA IMOGEN ADMU/RF / PHI | B29: 15 - 10 | H29: 13 | I29: =INDIRECT("C" & (6 + ($H29-1)*4)) -> (7) BUSTOS MICKYLE REIN | J29: =INDIRECT("C" & (14 + ($H29-1)*4)) -> (2) DINOY IVY CLAIRE | K29: =INDIRECT("D" & (10 + ($H29-1)*4)) -> (2) DINOY IVY CLAIRE | L29: =INDIRECT("D" & (11 + ($H29-1)*4)) -> 15 - 9 12:00 PM
C30: (4) GOMEZ JULIANA MA. BEATRICE | H30: 1 | I30: =INDIRECT("D" & (10 + ($H30-1)*4)) -> (1) ABELLA HANNIEL | J30: =INDIRECT("D" & (26 + ($H30-1)*4)) -> (4) GOMEZ JULIANA MA. BEATRICE | K30: =INDIRECT("E" & (18 + ($H30-1)*4)) -> (1) ABELLA HANNIEL | L30: =INDIRECT("E" & (19 + ($H30-1)*4)) -> 15 - 11 12:38 PM
A31: (29) - BYE - | C31: 15 - 7 11:15 AM | H31: 9 | I31: =INDIRECT("D" & (10 + ($H31-1)*4)) -> (3) LARRAZABAL ALEXA | J31: =INDIRECT("D" & (26 + ($H31-1)*4)) -> (2) DINOY IVY CLAIRE | K31: =INDIRECT("E" & (18 + ($H31-1)*4)) -> (2) LARRAZABAL ALEXA | L31: =INDIRECT("E" & (19 + ($H31-1)*4)) -> 15 - 12 12:39 PM
B32: (4) GOMEZ JULIANA MA. BEATRICE | H32: 1 | I32: {=INDIRECT("E" & (18 + ($H32-1)*4))} -> (1) ABELLA HANNIEL | J32: {=INDIRECT("E" & (50 + ($H32-1)*4))} -> (2) LARRAZABAL ALEXA | K32: {=INDIRECT("F" & (34 + ($H32-1)*4))} -> (1) LARRAZABAL ALEXA | L32: {=INDIRECT("F" & (35 + ($H32-1)*4))} -> 15 - 14 1:22 PM
A33: (4) GOMEZ JULIANA MA. BEATRICE PMPA / PHI
F34: (1) LARRAZABAL ALEXA
A35: (3) LARRAZABAL ALEXA NTP / PHI | F35: 15 - 14 1:22 PM
B36: (3) LARRAZABAL ALEXA
A37: (30) - BYE -
C38: (3) LARRAZABAL ALEXA
A39: (19) BACCAY MARTINA JENE DLSZ / PHI | C39: 15 - 7 11:21 AM
B40: (14) MENDOZA JENNINA
...

Sheet all_legs_de_bouts
A1: leg | B1: right.fencer | C1: left.fencer | D1: winner | E1: score
A2: 1 | B2: ='Leg 1'!I2 -> (1) LARRAZABAL ALEXA NTP / PHI | C2: ='Leg 1'!J2 -> (32) TRINIDAD SOLANA MAYUMI EZKRIMA / PHI | D2: ='Leg 1'!K2 -> (1) LARRAZABAL ALEXA | E2: ='Leg 1'!L2 -> 15 - 5
A3: 1 | B3: ='Leg 1'!I3 -> (17) MANAOIS IRISH UE / PHI | C3: ='Leg 1'!J3 -> (16) ONG JICKLE CLAIN CF / PHI | D3: ='Leg 1'!K3 -> (16) ONG JICKLE CLAIN | E3: ='Leg 1'!L3 -> 15 - 8
A4: 1 | B4: ='Leg 1'!I4 -> (9) VILLAPANDO JHOLAN DLSU / PHI | C4: ='Leg 1'!J4 -> (24) BERNABE FRANCESCA BETTINA ADMU / PHI | D4: ='Leg 1'!K4 -> (9) BERNABE FRANCESCA BETTINA | E4: ='Leg 1'!L4 -> 15 - 13
A5: 1 | B5: ='Leg 1'!I5 -> (25) JIMENEZ JULIANNA UE / PHI | C5: ='Leg 1'!J5 -> (8) DINOY IVY CLAIRE MP / PHI | D5: ='Leg 1'!K5 -> (8) DINOY IVY CLAIRE | E5: ='Leg 1'!L5 -> 15 - 5
A6: 1 | B6: ='Leg 1'!I6 -> (5) VERGARA CYRRA DLSU / PHI | C6: ='Leg 1'!J6 -> (28) FELICIANO SUMMER LUCINE AF / PHI | D6: ='Leg 1'!K6 -> (5) VERGARA CYRRA | E6: ='Leg 1'!L6 -> 15 - 8
A7: 1 | B7: ='Leg 1'!I7 -> (21) BELEN FRANCES CAMILLE UP / PHI | C7: ='Leg 1'!J7 -> (12) MENDOZA JENNINA UP / PHI | D7: ='Leg 1'!K7 -> (12) MENDOZA JENNINA | E7: ='Leg 1'!L7 -> 15 - 2
A8: 1 | B8: ='Leg 1'!I8 -> (13) SALVADOR IVANA CF / PHI | C8: ='Leg 1'!J8 -> (20) NORO NAMI UP / PHI | D8: ='Leg 1'!K8 -> (13) NORO NAMI | E8: ='Leg 1'!L8 -> 15 - 8
A9: 1 | B9: ='Leg 1'!I9 -> (29) RAFAEL GAY MARIE RF / PHI | C9: ='Leg 1'!J9 -> (4) BALLESTEROS JULIANNA UP / PHI | D9: ='Leg 1'!K9 -> (4) BALLESTEROS JULIANNA | E9: ='Leg 1'!L9 -> 15 - 9
A10: 1 | B10: ='Leg 1'!I10 -> (3) CANLAS NINA DOMINIQUE UE / PHI | C10: ='Leg 1'!J10 -> (30) UY JANA ANNIKA CF / PHI | D10: ='Leg 1'!K10 -> (3) CANLAS NINA DOMINIQUE | E10: ='Leg 1'!L10 -> 15 - 12
A11: 1 | B11: ='Leg 1'!I11 -> (19) RAGOT MIKAELA NICOLE UE / PHI | C11: ='Leg 1'!J11 -> (14) GOMEZ JULIANA MA. BEATRICE MP / PHI | D11: ='Leg 1'!K11 -> (14) GOMEZ JULIANA MA. BEATRICE | E11: ='Leg 1'!L11 -> 15 - 7
A12: 1 | B12: ='Leg 1'!I12 -> (11) BUSTOS MICKYLE REIN RF / PHI | C12: ='Leg 1'!J12 -> (22) EDNILAG KRUPS KAYA DLSU / PHI | D12: ='Leg 1'!K12 -> (11) BUSTOS MICKYLE REIN | E12: ='Leg 1'!L12 -> 15 - 11
A13: 1 | B13: ='Leg 1'!I13 -> (27) TORRE PAPINA MARGUERITE AF / PHI | C13: ='Leg 1'!J13 -> (6) MATIAS ANDREA JENNELLE UE / PHI | D13: ='Leg 1'!K13 -> (6) MATIAS ANDREA JENNELLE | E13: ='Leg 1'!L13 -> 15 - 10
... A32: 1 | B32: ='Leg 1'!I32 -> (1) LARRAZABAL ALEXA | C32: ='Leg 1'!J32 -> (2) HARRISON ASHLEY MAE MICHELLE | D32: ='Leg 1'!K32 -> (1) LARRAZABAL ALEXA | E32: ='Leg 1'!L32 -> 15 - 13 1:47 PM
A33: 2 | B33: ='Leg 2'!I2 -> (1) SEVILLA JULIANA SHANE MP / PHI | C33: ='Leg 2'!J2 -> (64) - BYE - | D33: ='Leg 2'!K2 -> (1) SEVILLA JULIANA SHANE | E33: ='Leg 2'!L2 -> 0
A34: 2 | B34: ='Leg 2'!I3 -> (33) SIA SARAH-INGRID AURELIA RF / PHI | C34: ='Leg 2'!J3 -> (32) CAPUNO DAHLIA MAE USTFT / PHI | D34: ='Leg 2'!K3 -> (32) CAPUNO DAHLIA MAE | E34: ='Leg 2'!L3 -> 15 - 14
A35: 2 | B35: ='Leg 2'!I4 -> (17) DELOS SANTOS JAYMI NTP / PHI | C35: ='Leg 2'!J4 -> (48) - BYE - | D35: ='Leg 2'!K4 -> (17) DELOS SANTOS JAYMI | E35: ='Leg 2'!L4 -> 0
A36: 2 | B36: ='Leg 2'!I5 -> (49) - BYE - | C36: ='Leg 2'!J5 -> (16) MENDOZA JENNINA UP / PHI | D36: ='Leg 2'!K5 -> (16) MENDOZA JENNINA | E36: ='Leg 2'!L5 -> 0
A37: 2 | B37: ='Leg 2'!I6 -> (9) EDNILAG KRUPS KAYA DLSU / PHI | C37: ='Leg 2'!J6 -> (56) - BYE - | D37: ='Leg 2'!K6 -> (9) EDNILAG KRUPS KAYA | E37: ='Leg 2'!L6 -> 0
A38: 2 | B38: ='Leg 2'!I7 -> (41) - BYE - | C38: ='Leg 2'!J7 -> (24) SANDOVAL JUSTA ANDREA CF / PHI | D38: ='Leg 2'!K7 -> (24) SANDOVAL JUSTA ANDREA | E38: ='Leg 2'!L7 -> 0
A39: 2 | B39: ='Leg 2'!I8 -> (25) SALVADOR IVANA CF / PHI | C39: ='Leg 2'!J8 -> (40) - BYE - | D39: ='Leg 2'!K8 -> (25) SALVADOR IVANA | E39: ='Leg 2'!L8 -> 0
A40: 2 | B40: ='Leg 2'!I9 -> (57) - BYE - | C40: ='Leg 2'!J9 -> (8) TAPALES ENDIRAJ MARGARET UP / PHI | D40: ='Leg 2'!K9 -> (8) TAPALES ENDIRAJ MARGARET | E40: ='Leg 2'!L9 -> 0
A41: 2 | B41: ='Leg 2'!I10 -> (5) MATIAS ANDREA JENNELLE UE / PHI | C41: ='Leg 2'!J10 -> (60) - BYE - | D41: ='Leg 2'!K10 -> (5) MATIAS ANDREA JENNELLE | E41: ='Leg 2'!L10 -> 0
A42: 2 | B42: ='Leg 2'!I11 -> (37) - BYE - | C42: ='Leg 2'!J11 -> (28) TORRE PAPINA MARGUERITE AF / PHI | D42: ='Leg 2'!K11 -> (28) TORRE PAPINA MARGUERITE | E42: ='Leg 2'!L11 -> 0
A43: 2 | B43: ='Leg 2'!I12 -> (21) DELA CRUZ CHIARA MICHAELA UPFC / PHI | C43: ='Leg 2'!J12 -> (44) - BYE - | D43: ='Leg 2'!K12 -> (21) DELA CRUZ CHIARA MICHAELA | E43: ='Leg 2'!L12 -> 0
A44: 2 | B44: ='Leg 2'!I13 -> (53) - BYE - | C44: ='Leg 2'!J13 -> (12) SCHOFIELD CYRYLLE ANNE UE / PHI | D44: ='Leg 2'!K13 -> (12) SCHOFIELD CYRYLLE ANNE | E44: ='Leg 2'!L13 -> 0
... A95: 2 | B95: ='Leg 2'!I64 -> (1) EDNILAG KRUPS KAYA | C95: ='Leg 2'!J64 -> (2) LARRAZABAL ALEXA | D95: ='Leg 2'!K64 -> (1) LARRAZABAL ALEXA | E95: ='Leg 2'!L64 -> 15 - 8 2:34 PM
A96: 3 | B96: ='Leg 3'!I2 -> (1) LARRAZABAL ALEXA NTP / PHI | C96: ='Leg 3'!J2 -> (32) SIA SARAH-INGRID AURELIA RF / PHI | D96: ='Leg 3'!K2 -> (1) LARRAZABAL ALEXA | E96: ='Leg 3'!L2 -> 15 - 4
A97: 3 | B97: ='Leg 3'!I3 -> (17) ONG JICKLE CLAIN CF / PHI | C97: ='Leg 3'!J3 -> (16) MANAOIS IRISH UE / PHI | D97: ='Leg 3'!K3 -> (16) ONG JICKLE CLAIN | E97: ='Leg 3'!L3 -> 15 - 14
A98: 3 | B98: ='Leg 3'!I4 -> (9) TRINIDAD SOLANA MAYUMI EZKRIMA / PHI | C98: ='Leg 3'!J4 -> (24) GEPUELA CATHERINE THERESE UP / PHI | D98: ='Leg 3'!K4 -> (9) TRINIDAD SOLANA MAYUMI | E98: ='Leg 3'!L4 -> 15 - 13
A99: 3 | B99: ='Leg 3'!I5 -> (25) BARRIENTOS ANDREA HCFC / PHI | C99: ='Leg 3'!J5 -> (8) HARRISON ASHLEY MAE MICHELLE NTP / PHI | D99: ='Leg 3'!K5 -> (8) HARRISON ASHLEY MAE MICHELLE | E99: ='Leg 3'!L5 -> 15 - 3
A100: 3 | B100: ='Leg 3'!I6 -> (5) SCHOFIELD CYRYLLE ANNE UE / PHI | C100: ='Leg 3'!J6 -> (28) SANDOVAL JUSTA ANDREA CF / PHI | D100: ='Leg 3'!K6 -> (5) SCHOFIELD CYRYLLE ANNE | E100: ='Leg 3'!L6 -> 15 - 11
A101: 3 | B101: ='Leg 3'!I7 -> (21) TORRE PAPINA MARGUERITE AF / PHI | C101: ='Leg 3'!J7 -> (12) BUSTOS MICKYLE REIN RF / PHI | D101: ='Leg 3'!K7 -> (12) BUSTOS MICKYLE REIN | E101: ='Leg 3'!L7 -> 15 - 6
A102: 3 | B102: ='Leg 3'!I8 -> (13) CANLAS NINA DOMINIQUE UE / PHI | C102: ='Leg 3'!J8 -> (20) SYKAT ROBYN NOELLE RF / PHI | D102: ='Leg 3'!K8 -> (13) CANLAS NINA DOMINIQUE | E102: ='Leg 3'!L8 -> 15 - 8
A103: 3 | B103: ='Leg 3'!I9 -> (29) DELA CRUZ CHIARA MICHAELA UPFC / PHI | C103: ='Leg 3'!J9 -> (4) ABELLA HANNIEL NTP / PHI | D103: ='Leg 3'!K9 -> (4) ABELLA HANNIEL | E103: ='Leg 3'!L9 -> 15 - 7
A104: 3 | B104: ='Leg 3'!I10 -> (3) GOMEZ JULIANA MA. BEATRICE MP / PHI | C104: ='Leg 3'!J10 -> (30) TAPALES ENDIRAJ MARGARET UP / PHI | D104: ='Leg 3'!K10 -> (3) GOMEZ JULIANA MA. BEATRICE | E104: ='Leg 3'!L10 -> 15 - 14
A105: 3 | B105: ='Leg 3'!I11 -> (19) NORO NAMI UP / PHI | C105: ='Leg 3'!J11 -> (14) RAGOT MIKAELA NICOLE UE / PHI | D105: ='Leg 3'!K11 -> (14) NORO NAMI | E105: ='Leg 3'!L11 -> 15 - 9
